Workbook

Sheet Orari
A1: DAL | B1: 12/10/2026 | D1: AL | E1: 18/10/2026
A3: NOMINATIVO / TURNO | B3: RUOLO | C3: lunedì 12 ottobre 2026 | G3: martedì 13 ottobre 2026 | K3: mercoledì 14 ottobre 2026 | O3: giovedì 15 ottobre 2026 | S3: venerdì 16 ottobre 2026 | W3: sabato 17 ottobre 2026 | AA3: domenica 18 ottobre 2026 | AE3: TOTALE ORE | AF3: ORE CONTRATTO
C4: Mattino | E4: Pomeriggio | G4: Mattino | I4: Pomeriggio | K4: Mattino | M4: Pomeriggio | O4: Mattino | Q4: Pomeriggio | S4: Mattino | U4: Pomeriggio | W4: Mattino | Y4: Pomeriggio | AA4: Mattino | AC4: Pomeriggio
C5: E | D5: U | E5: E | F5: U | G5: E | H5: U | I5: E | J5: U | K5: E | L5: U | M5: E | N5: U | O5: E | P5: U | Q5: E | R5: U | S5: E | T5: U | U5: E | V5: U | W5: E | X5: U | Y5: E | Z5: U | AA5: E | AB5: U | AC5: E | AD5: U
A6: BRUNI LAURA | B6: Addetto vendite | C6: 0.41666667 | D6: 0.625 | I6: 0.625 | J6: 0.83333333 | K6: RIPOSO | O6: 0.41666667 | P6: 0.625 | U6: 0.58333333 | V6: 0.83333333 | W6: 0.41666667 | X6: 0.625 | Y6: 0.66666667 | Z6: 0.83333333 | AA6: RIPOSO | AE6: =ROUND(24*(N(D6)-N(C6)+N(F6)-N(E6)+N(H6)-N(G6)+N(J6)-N(I6)+N(L6)-N(K6)+N(N6)-N(M6)+N(P6)-N(O6)+N(R6)-N(Q6)+N(T6)-N(S6)+N(V6)-N(U6)+N(X6)-N(W6)+N(Z6)-N(Y6)+N(AB6)-N(AA6)+N(AD6)-N(AC6)),2) | AF6: 30
A7: DE SANTIS MIRKO 🔑 | B7: Vicedirettore | C7: RIPOSO | G7: 0.375 | H7: 0.625 | I7: 0.66666667 | J7: 0.83333333 | K7: 0.375 | L7: 0.625 | M7: 0.66666667 | N7: 0.83333333 | O7: RIPOSO | S7: 0.375 | T7: 0.625 | W7: 0.45833333 | X7: 0.58333333 | Y7: 0.625 | Z7: 0.875 | AA7: 0.41666667 | AB7: 0.54166667 | AC7: 0.58333333 | AD7: 0.875 | AE7: =ROUND(24*(N(D7)-N(C7)+N(F7)-N(E7)+N(H7)-N(G7)+N(J7)-N(I7)+N(L7)-N(K7)+N(N7)-N(M7)+N(P7)-N(O7)+N(R7)-N(Q7)+N(T7)-N(S7)+N(V7)-N(U7)+N(X7)-N(W7)+N(Z7)-N(Y7)+N(AB7)-N(AA7)+N(AD7)-N(AC7)),2) | AF7: 44-45
A8: CILIANI ANDREA 🔑 | B8: Addetto vendite | E8: 0.625 | F8: 0.875 | G8: 0.41666667 | H8: 0.66666667 | I8: 0.70833333 | J8: 0.875 | K8: RIPOSO | Q8: 0.625 | R8: 0.875 | S8: RIPOSO | W8: 0.375 | X8: 0.625 | Y8: 0.66666667 | Z8: 0.79166667 | AA8: 0.375 | AB8: 0.5 | AC8: 0.54166667 | AD8: 0.79166667 | AE8: =ROUND(24*(N(D8)-N(C8)+N(F8)-N(E8)+N(H8)-N(G8)+N(J8)-N(I8)+N(L8)-N(K8)+N(N8)-N(M8)+N(P8)-N(O8)+N(R8)-N(Q8)+N(T8)-N(S8)+N(V8)-N(U8)+N(X8)-N(W8)+N(Z8)-N(Y8)+N(AB8)-N(AA8)+N(AD8)-N(AC8)),2) | AF8: 40
A9: DI ERASMO GABRIELE | B9: Addetto vendite | E9: 0.625 | F9: 0.875 | G9: RIPOSO | K9: 0.41666667 | L9: 0.66666667 | M9: 0.70833333 | N9: 0.875 | Q9: 0.625 | R9: 0.875 | S9: RIPOSO | W9: 0.375 | X9: 0.54166667 | Y9: 0.58333333 | Z9: 0.79166667 | AA9: 0.45833333 | AB9: 0.58333333 | AC9: 0.625 | AD9: 0.875 | AE9: =ROUND(24*(N(D9)-N(C9)+N(F9)-N(E9)+N(H9)-N(G9)+N(J9)-N(I9)+N(L9)-N(K9)+N(N9)-N(M9)+N(P9)-N(O9)+N(R9)-N(Q9)+N(T9)-N(S9)+N(V9)-N(U9)+N(X9)-N(W9)+N(Z9)-N(Y9)+N(AB9)-N(AA9)+N(AD9)-N(AC9)),2) | AF9: 40
A10: GERMANO ALESSANDRO | B10: Addetto vendite | C10: 0.375 | D10: 0.625 | E10: 0.66666667 | F10: 0.79166667 | G10: RIPOSO | M10: 0.625 | N10: 0.875 | O10: 0.375 | P10: 0.625 | S10: 0.41666667 | T10: 0.58333333 | U10: 0.625 | V10: 0.875 | W10: 0.45833333 | X10: 0.58333333 | Y10: 0.625 | Z10: 0.875 | AA10: RIPOSO | AE10: =ROUND(24*(N(D10)-N(C10)+N(F10)-N(E10)+N(H10)-N(G10)+N(J10)-N(I10)+N(L10)-N(K10)+N(N10)-N(M10)+N(P10)-N(O10)+N(R10)-N(Q10)+N(T10)-N(S10)+N(V10)-N(U10)+N(X10)-N(W10)+N(Z10)-N(Y10)+N(AB10)-N(AA10)+N(AD10)-N(AC10)),2) | AF10: 40
A11: PROIETTI BENEDETTA 🔑 | B11: Cassiera | C11: 0.375 | D11: 0.54166667 | E11: 0.58333333 | F11: 0.70833333 | G11: RIPOSO | K11: 0.41666667 | L11: 0.54166667 | M11: 0.58333333 | N11: 0.875 | O11: 0.375 | P11: 0.54166667 | Q11: 0.58333333 | R11: 0.75 | S11: 0.45833333 | T11: 0.54166667 | U11: 0.58333333 | V11: 0.875 | W11: 0.375 | X11: 0.625 | AA11: RIPOSO | AE11: =ROUND(24*(N(D11)-N(C11)+N(F11)-N(E11)+N(H11)-N(G11)+N(J11)-N(I11)+N(L11)-N(K11)+N(N11)-N(M11)+N(P11)-N(O11)+N(R11)-N(Q11)+N(T11)-N(S11)+N(V11)-N(U11)+N(X11)-N(W11)+N(Z11)-N(Y11)+N(AB11)-N(AA11)+N(AD11)-N(AC11)),2) | AF11: 40
A12: LORETI MARTINA | B12: Cassiera | E12: 0.70833333 | F12: 0.875 | G12: 0.375 | H12: 0.58333333 | K12: RIPOSO | O12: RIPOSO | S12: 0.375 | T12: 0.58333333 | W12: RIPOSO | AA12: 0.41666667 | AB12: 0.58333333 | AC12: 0.625 | AD12: 0.875 | AE12: =ROUND(24*(N(D12)-N(C12)+N(F12)-N(E12)+N(H12)-N(G12)+N(J12)-N(I12)+N(L12)-N(K12)+N(N12)-N(M12)+N(P12)-N(O12)+N(R12)-N(Q12)+N(T12)-N(S12)+N(V12)-N(U12)+N(X12)-N(W12)+N(Z12)-N(Y12)+N(AB12)-N(AA12)+N(AD12)-N(AC12)),2) | AF12: 24
A13: PRESTI DEBORA | B13: Cassiera | C13: RIPOSO | I13: 0.625 | J13: 0.875 | K13: 0.375 | L13: 0.58333333 | O13: 0.41666667 | P13: 0.58333333 | U13: 0.625 | V13: 0.79166667 | Y13: 0.66666667 | Z13: 0.875 | AA13: RIPOSO | AE13: =ROUND(24*(N(D13)-N(C13)+N(F13)-N(E13)+N(H13)-N(G13)+N(J13)-N(I13)+N(L13)-N(K13)+N(N13)-N(M13)+N(P13)-N(O13)+N(R13)-N(Q13)+N(T13)-N(S13)+N(V13)-N(U13)+N(X13)-N(W13)+N(Z13)-N(Y13)+N(AB13)-N(AA13)+N(AD13)-N(AC13)),2) | AF13: 24
A14: PELLEGRINI GIORGIA | B14: Cassiera | C14: 0.45833333 | D14: 0.58333333 | I14: 0.58333333 | J14: 0.75 | K14: RIPOSO | Q14: 0.70833333 | R14: 0.875 | S14: RIPOSO | Y14: 0.625 | Z14: 0.79166667 | AA14: 0.375 | AB14: 0.54166667 | AC14: 0.58333333 | AD14: 0.79166667 | AE14: =ROUND(24*(N(D14)-N(C14)+N(F14)-N(E14)+N(H14)-N(G14)+N(J14)-N(I14)+N(L14)-N(K14)+N(N14)-N(M14)+N(P14)-N(O14)+N(R14)-N(Q14)+N(T14)-N(S14)+N(V14)-N(U14)+N(X14)-N(W14)+N(Z14)-N(Y14)+N(AB14)-N(AA14)+N(AD14)-N(AC14)),2) | AF14: 24
A15: DIANA LUIGI | B15: Magazziniere | C15: 0.375 | D15: 0.54166667 | E15: 0.58333333 | F15: 0.75 | G15: 0.375 | H15: 0.54166667 | I15: 0.58333333 | J15: 0.75 | K15: 0.375 | L15: 0.54166667 | M15: 0.58333333 | N15: 0.75 | O15: 0.375 | P15: 0.54166667 | Q15: 0.58333333 | R15: 0.75 | S15: 0.375 | T15: 0.54166667 | U15: 0.58333333 | V15: 0.75 | W15: RIPOSO | AA15: RIPOSO | AE15: =ROUND(24*(N(D15)-N(C15)+N(F15)-N(E15)+N(H15)-N(G15)+N(J15)-N(I15)+N(L15)-N(K15)+N(N15)-N(M15)+N(P15)-N(O15)+N(R15)-N(Q15)+N(T15)-N(S15)+N(V15)-N(U15)+N(X15)-N(W15)+N(Z15)-N(Y15)+N(AB15)-N(AA15)+N(AD15)-N(AC15)),2) | AF15: 40
A17: 🔑 = ha le chiavi (apre/chiude). Ogni giorno un tesserato apre alle 9:00 e uno chiude alle 21:00.
A18: Riposi spostati rispetto alla settimana 5-11 ottobre: mai lo stesso giorno, distanza tra un riposo e l'altro da 2 a 5 giorni.
A19: Orari delle casse (Benedetta, Martina, Debora, Giorgia) presi dal foglio del negozio; Luigi Diana lun-ven 9-13 / 14-18.
A20: Sabato giornata intera per tutto il reparto, domenica niente mezze giornate; il terzo addetto di reparto messo di preferenza al pomeriggio.
A21: Il foglio 'Copertura' conta ora per ora quante persone ci sono (si aggiorna da solo se modifichi gli orari).

Sheet Copertura
A1: Persone presenti ora per ora (calcolate dal foglio Orari)
A3: ADDETTI REPARTO (vendite + vicedirettore) — obiettivo almeno 2
A4: Giorno | B4: 9-10 | C4: 10-11 | D4: 11-12 | E4: 12-13 | F4: 13-14 | G4: 14-15 | H4: 15-16 | I4: 16-17 | J4: 17-18 | K4: 18-19 | L4: 19-20 | M4: 20-21
A5: lunedì 12 ottobre 2026 | B5: =SUMPRODUCT((((Orari!$B$6:$B$15="Addetto vendite")+(Orari!$B$6:$B$15="Vicedirettore"))>0)*(((Orari!$C$6:$C$15<=TIME(9,30,0))*(Orari!$D$6:$D$15>TIME(9,30,0)))+((Orari!$E$6:$E$15<=TIME(9,30,0))*(Orari!$F$6:$F$15>TIME(9,30,0))))) | C5: =SUMPRODUCT((((Orari!$B$6:$B$15="Addetto vendite")+(Orari!$B$6:$B$15="Vicedirettore"))>0)*(((Orari!$C$6:$C$15<=TIME(10,30,0))*(Orari!$D$6:$D$15>TIME(10,30,0)))+((Orari!$E$6:$E$15<=TIME(10,30,0))*(Orari!$F$6:$F$15>TIME(10,30,0))))) | D5: =SUMPRODUCT((((Orari!$B$6:$B$15="Addetto vendite")+(Orari!$B$6:$B$15="Vicedirettore"))>0)*(((Orari!$C$6:$C$15<=TIME(11,30,0))*(Orari!$D$6:$D$15>TIME(11,30,0)))+((Orari!$E$6:$E$15<=TIME(11,30,0))*(Orari!$F$6:$F$15>TIME(11,30,0))))) | E5: =SUMPRODUCT((((Orari!$B$6:$B$15="Addetto vendite")+(Orari!$B$6:$B$15="Vicedirettore"))>0)*(((Orari!$C$6:$C$15<=TIME(12,30,0))*(Orari!$D$6:$D$15>TIME(12,30,0)))+((Orari!$E$6:$E$15<=TIME(12,30,0))*(Orari!$F$6:$F$15>TIME(12,30,0))))) | F5: =SUMPRODUCT((((Orari!$B$6:$B$15="Addetto vendite")+(Orari!$B$6:$B$15="Vicedirettore"))>0)*(((Orari!$C$6:$C$15<=TIME(13,30,0))*(Orari!$D$6:$D$15>TIME(13,30,0)))+((Orari!$E$6:$E$15<=TIME(13,30,0))*(Orari!$F$6:$F$15>TIME(13,30,0))))) | G5: =SUMPRODUCT((((Orari!$B$6:$B$15="Addetto vendite")+(Orari!$B$6:$B$15="Vicedirettore"))>0)*(((Orari!$C$6:$C$15<=TIME(14,30,0))*(Orari!$D$6:$D$15>TIME(14,30,0)))+((Orari!$E$6:$E$15<=TIME(14,30,0))*(Orari!$F$6:$F$15>TIME(14,30,0))))) | H5: =SUMPRODUCT((((Orari!$B$6:$B$15="Addetto vendite")+(Orari!$B$6:$B$15="Vicedirettore"))>0)*(((Orari!$C$6:$C$15<=TIME(15,30,0))*(Orari!$D$6:$D$15>TIME(15,30,0)))+((Orari!$E$6:$E$15<=TIME(15,30,0))*(Orari!$F$6:$F$15>TIME(15,30,0))))) | I5: =SUMPRODUCT((((Orari!$B$6:$B$15="Addetto vendite")+(Orari!$B$6:$B$15="Vicedirettore"))>0)*(((Orari!$C$6:$C$15<=TIME(16,30,0))*(Orari!$D$6:$D$15>TIME(16,30,0)))+((Orari!$E$6:$E$15<=TIME(16,30,0))*(Orari!$F$6:$F$15>TIME(16,30,0))))) | J5: =SUMPRODUCT((((Orari!$B$6:$B$15="Addetto vendite")+(Orari!$B$6:$B$15="Vicedirettore"))>0)*(((Orari!$C$6:$C$15<=TIME(17,30,0))*(Orari!$D$6:$D$15>TIME(17,30,0)))+((Orari!$E$6:$E$15<=TIME(17,30,0))*(Orari!$F$6:$F$15>TIME(17,30,0))))) | K5: =SUMPRODUCT((((Orari!$B$6:$B$15="Addetto vendite")+(Orari!$B$6:$B$15="Vicedirettore"))>0)*(((Orari!$C$6:$C$15<=TIME(18,30,0))*(Orari!$D$6:$D$15>TIME(18,30,0)))+((Orari!$E$6:$E$15<=TIME(18,30,0))*(Orari!$F$6:$F$15>TIME(18,30,0))))) | L5: =SUMPRODUCT((((Orari!$B$6:$B$15="Addetto vendite")+(Orari!$B$6:$B$15="Vicedirettore"))>0)*(((Orari!$C$6:$C$15<=TIME(19,30,0))*(Orari!$D$6:$D$15>TIME(19,30,0)))+((Orari!$E$6:$E$15<=TIME(19,30,0))*(Orari!$F$6:$F$15>TIME(19,30,0))))) | M5: =SUMPRODUCT((((Orari!$B$6:$B$15="Addetto vendite")+(Orari!$B$6:$B$15="Vicedirettore"))>0)*(((Orari!$C$6:$C$15<=TIME(20,30,0))*(Orari!$D$6:$D$15>TIME(20,30,0)))+((Orari!$E$6:$E$15<=TIME(20,30,0))*(Orari!$F$6:$F$15>TIME(20,30,0)))))
A6: martedì 13 ottobre 2026 | B6: =SUMPRODUCT((((Orari!$B$6:$B$15="Addetto vendite")+(Orari!$B$6:$B$15="Vicedirettore"))>0)*(((Orari!$G$6:$G$15<=TIME(9,30,0))*(Orari!$H$6:$H$15>TIME(9,30,0)))+((Orari!$I$6:$I$15<=TIME(9,30,0))*(Orari!$J$6:$J$15>TIME(9,30,0))))) | C6: =SUMPRODUCT((((Orari!$B$6:$B$15="Addetto vendite")+(Orari!$B$6:$B$15="Vicedirettore"))>0)*(((Orari!$G$6:$G$15<=TIME(10,30,0))*(Orari!$H$6:$H$15>TIME(10,30,0)))+((Orari!$I$6:$I$15<=TIME(10,30,0))*(Orari!$J$6:$J$15>TIME(10,30,0))))) | D6: =SUMPRODUCT((((Orari!$B$6:$B$15="Addetto vendite")+(Orari!$B$6:$B$15="Vicedirettore"))>0)*(((Orari!$G$6:$G$15<=TIME(11,30,0))*(Orari!$H$6:$H$15>TIME(11,30,0)))+((Orari!$I$6:$I$15<=TIME(11,30,0))*(Orari!$J$6:$J$15>TIME(11,30,0))))) | E6: =SUMPRODUCT((((Orari!$B$6:$B$15="Addetto vendite")+(Orari!$B$6:$B$15="Vicedirettore"))>0)*(((Orari!$G$6:$G$15<=TIME(12,30,0))*(Orari!$H$6:$H$15>TIME(12,30,0)))+((Orari!$I$6:$I$15<=TIME(12,30,0))*(Orari!$J$6:$J$15>TIME(12,30,0))))) | F6: =SUMPRODUCT((((Orari!$B$6:$B$15="Addetto vendite")+(Orari!$B$6:$B$15="Vicedirettore"))>0)*(((Orari!$G$6:$G$15<=TIME(13,30,0))*(Orari!$H$6:$H$15>TIME(13,30,0)))+((Orari!$I$6:$I$15<=TIME(13,30,0))*(Orari!$J$6:$J$15>TIME(13,30,0))))) | G6: =SUMPRODUCT((((Orari!$B$6:$B$15="Addetto vendite")+(Orari!$B$6:$B$15="Vicedirettore"))>0)*(((Orari!$G$6:$G$15<=TIME(14,30,0))*(Orari!$H$6:$H$15>TIME(14,30,0)))+((Orari!$I$6:$I$15<=TIME(14,30,0))*(Orari!$J$6:$J$15>TIME(14,30,0))))) | H6: =SUMPRODUCT((((Orari!$B$6:$B$15="Addetto vendite")+(Orari!$B$6:$B$15="Vicedirettore"))>0)*(((Orari!$G$6:$G$15<=TIME(15,30,0))*(Orari!$H$6:$H$15>TIME(15,30,0)))+((Orari!$I$6:$I$15<=TIME(15,30,0))*(Orari!$J$6:$J$15>TIME(15,30,0))))) | I6: =SUMPRODUCT((((Orari!$B$6:$B$15="Addetto vendite")+(Orari!$B$6:$B$15="Vicedirettore"))>0)*(((Orari!$G$6:$G$15<=TIME(16,30,0))*(Orari!$H$6:$H$15>TIME(16,30,0)))+((Orari!$I$6:$I$15<=TIME(16,30,0))*(Orari!$J$6:$J$15>TIME(16,30,0))))) | J6: =SUMPRODUCT((((Orari!$B$6:$B$15="Addetto vendite")+(Orari!$B$6:$B$15="Vicedirettore"))>0)*(((Orari!$G$6:$G$15<=TIME(17,30,0))*(Orari!$H$6:$H$15>TIME(17,30,0)))+((Orari!$I$6:$I$15<=TIME(17,30,0))*(Orari!$J$6:$J$15>TIME(17,30,0))))) | K6: =SUMPRODUCT((((Orari!$B$6:$B$15="Addetto vendite")+(Orari!$B$6:$B$15="Vicedirettore"))>0)*(((Orari!$G$6:$G$15<=TIME(18,30,0))*(Orari!$H$6:$H$15>TIME(18,30,0)))+((Orari!$I$6:$I$15<=TIME(18,30,0))*(Orari!$J$6:$J$15>TIME(18,30,0))))) | L6: =SUMPRODUCT((((Orari!$B$6:$B$15="Addetto vendite")+(Orari!$B$6:$B$15="Vicedirettore"))>0)*(((Orari!$G$6:$G$15<=TIME(19,30,0))*(Orari!$H$6:$H$15>TIME(19,30,0)))+((Orari!$I$6:$I$15<=TIME(19,30,0))*(Orari!$J$6:$J$15>TIME(19,30,0))))) | M6: =SUMPRODUCT((((Orari!$B$6:$B$15="Addetto vendite")+(Orari!$B$6:$B$15="Vicedirettore"))>0)*(((Orari!$G$6:$G$15<=TIME(20,30,0))*(Orari!$H$6:$H$15>TIME(20,30,0)))+((Orari!$I$6:$I$15<=TIME(20,30,0))*(Orari!$J$6:$J$15>TIME(20,30,0)))))
A7: mercoledì 14 ottobre 2026 | B7: =SUMPRODUCT((((Orari!$B$6:$B$15="Addetto vendite")+(Orari!$B$6:$B$15="Vicedirettore"))>0)*(((Orari!$K$6:$K$15<=TIME(9,30,0))*(Orari!$L$6:$L$15>TIME(9,30,0)))+((Orari!$M$6:$M$15<=TIME(9,30,0))*(Orari!$N$6:$N$15>TIME(9,30,0))))) | C7: =SUMPRODUCT((((Orari!$B$6:$B$15="Addetto vendite")+(Orari!$B$6:$B$15="Vicedirettore"))>0)*(((Orari!$K$6:$K$15<=TIME(10,30,0))*(Orari!$L$6:$L$15>TIME(10,30,0)))+((Orari!$M$6:$M$15<=TIME(10,30,0))*(Orari!$N$6:$N$15>TIME(10,30,0))))) | D7: =SUMPRODUCT((((Orari!$B$6:$B$15="Addetto vendite")+(Orari!$B$6:$B$15="Vicedirettore"))>0)*(((Orari!$K$6:$K$15<=TIME(11,30,0))*(Orari!$L$6:$L$15>TIME(11,30,0)))+((Orari!$M$6:$M$15<=TIME(11,30,0))*(Orari!$N$6:$N$15>TIME(11,30,0))))) | E7: =SUMPRODUCT((((Orari!$B$6:$B$15="Addetto vendite")+(Orari!$B$6:$B$15="Vicedirettore"))>0)*(((Orari!$K$6:$K$15<=TIME(12,30,0))*(Orari!$L$6:$L$15>TIME(12,30,0)))+((Orari!$M$6:$M$15<=TIME(12,30,0))*(Orari!$N$6:$N$15>TIME(12,30,0))))) | F7: =SUMPRODUCT((((Orari!$B$6:$B$15="Addetto vendite")+(Orari!$B$6:$B$15="Vicedirettore"))>0)*(((Orari!$K$6:$K$15<=TIME(13,30,0))*(Orari!$L$6:$L$15>TIME(13,30,0)))+((Orari!$M$6:$M$15<=TIME(13,30,0))*(Orari!$N$6:$N$15>TIME(13,30,0))))) | G7: =SUMPRODUCT((((Orari!$B$6:$B$15="Addetto vendite")+(Orari!$B$6:$B$15="Vicedirettore"))>0)*(((Orari!$K$6:$K$15<=TIME(14,30,0))*(Orari!$L$6:$L$15>TIME(14,30,0)))+((Orari!$M$6:$M$15<=TIME(14,30,0))*(Orari!$N$6:$N$15>TIME(14,30,0))))) | H7: =SUMPRODUCT((((Orari!$B$6:$B$15="Addetto vendite")+(Orari!$B$6:$B$15="Vicedirettore"))>0)*(((Orari!$K$6:$K$15<=TIME(15,30,0))*(Orari!$L$6:$L$15>TIME(15,30,0)))+((Orari!$M$6:$M$15<=TIME(15,30,0))*(Orari!$N$6:$N$15>TIME(15,30,0))))) | I7: =SUMPRODUCT((((Orari!$B$6:$B$15="Addetto vendite")+(Orari!$B$6:$B$15="Vicedirettore"))>0)*(((Orari!$K$6:$K$15<=TIME(16,30,0))*(Orari!$L$6:$L$15>TIME(16,30,0)))+((Orari!$M$6:$M$15<=TIME(16,30,0))*(Orari!$N$6:$N$15>TIME(16,30,0))))) | J7: =SUMPRODUCT((((Orari!$B$6:$B$15="Addetto vendite")+(Orari!$B$6:$B$15="Vicedirettore"))>0)*(((Orari!$K$6:$K$15<=TIME(17,30,0))*(Orari!$L$6:$L$15>TIME(17,30,0)))+((Orari!$M$6:$M$15<=TIME(17,30,0))*(Orari!$N$6:$N$15>TIME(17,30,0))))) | K7: =SUMPRODUCT((((Orari!$B$6:$B$15="Addetto vendite")+(Orari!$B$6:$B$15="Vicedirettore"))>0)*(((Orari!$K$6:$K$15<=TIME(18,30,0))*(Orari!$L$6:$L$15>TIME(18,30,0)))+((Orari!$M$6:$M$15<=TIME(18,30,0))*(Orari!$N$6:$N$15>TIME(18,30,0))))) | L7: =SUMPRODUCT((((Orari!$B$6:$B$15="Addetto vendite")+(Orari!$B$6:$B$15="Vicedirettore"))>0)*(((Orari!$K$6:$K$15<=TIME(19,30,0))*(Orari!$L$6:$L$15>TIME(19,30,0)))+((Orari!$M$6:$M$15<=TIME(19,30,0))*(Orari!$N$6:$N$15>TIME(19,30,0))))) | M7: =SUMPRODUCT((((Orari!$B$6:$B$15="Addetto vendite")+(Orari!$B$6:$B$15="Vicedirettore"))>0)*(((Orari!$K$6:$K$15<=TIME(20,30,0))*(Orari!$L$6:$L$15>TIME(20,30,0)))+((Orari!$M$6:$M$15<=TIME(20,30,0))*(Orari!$N$6:$N$15>TIME(20,30,0)))))
A8: giovedì 15 ottobre 2026 | B8: =SUMPRODUCT((((Orari!$B$6:$B$15="Addetto vendite")+(Orari!$B$6:$B$15="Vicedirettore"))>0)*(((Orari!$O$6:$O$15<=TIME(9,30,0))*(Orari!$P$6:$P$15>TIME(9,30,0)))+((Orari!$Q$6:$Q$15<=TIME(9,30,0))*(Orari!$R$6:$R$15>TIME(9,30,0))))) | C8: =SUMPRODUCT((((Orari!$B$6:$B$15="Addetto vendite")+(Orari!$B$6:$B$15="Vicedirettore"))>0)*(((Orari!$O$6:$O$15<=TIME(10,30,0))*(Orari!$P$6:$P$15>TIME(10,30,0)))+((Orari!$Q$6:$Q$15<=TIME(10,30,0))*(Orari!$R$6:$R$15>TIME(10,30,0))))) | D8: =SUMPRODUCT((((Orari!$B$6:$B$15="Addetto vendite")+(Orari!$B$6:$B$15="Vicedirettore"))>0)*(((Orari!$O$6:$O$15<=TIME(11,30,0))*(Orari!$P$6:$P$15>TIME(11,30,0)))+((Orari!$Q$6:$Q$15<=TIME(11,30,0))*(Orari!$R$6:$R$15>TIME(11,30,0))))) | E8: =SUMPRODUCT((((Orari!$B$6:$B$15="Addetto vendite")+(Orari!$B$6:$B$15="Vicedirettore"))>0)*(((Orari!$O$6:$O$15<=TIME(12,30,0))*(Orari!$P$6:$P$15>TIME(12,30,0)))+((Orari!$Q$6:$Q$15<=TIME(12,30,0))*(Orari!$R$6:$R$15>TIME(12,30,0))))) | F8: =SUMPRODUCT((((Orari!$B$6:$B$15="Addetto vendite")+(Orari!$B$6:$B$15="Vicedirettore"))>0)*(((Orari!$O$6:$O$15<=TIME(13,30,0))*(Orari!$P$6:$P$15>TIME(13,30,0)))+((Orari!$Q$6:$Q$15<=TIME(13,30,0))*(Orari!$R$6:$R$15>TIME(13,30,0))))) | G8: =SUMPRODUCT((((Orari!$B$6:$B$15="Addetto vendite")+(Orari!$B$6:$B$15="Vicedirettore"))>0)*(((Orari!$O$6:$O$15<=TIME(14,30,0))*(Orari!$P$6:$P$15>TIME(14,30,0)))+((Orari!$Q$6:$Q$15<=TIME(14,30,0))*(Orari!$R$6:$R$15>TIME(14,30,0))))) | H8: =SUMPRODUCT((((Orari!$B$6:$B$15="Addetto vendite")+(Orari!$B$6:$B$15="Vicedirettore"))>0)*(((Orari!$O$6:$O$15<=TIME(15,30,0))*(Orari!$P$6:$P$15>TIME(15,30,0)))+((Orari!$Q$6:$Q$15<=TIME(15,30,0))*(Orari!$R$6:$R$15>TIME(15,30,0))))) | I8: =SUMPRODUCT((((Orari!$B$6:$B$15="Addetto vendite")+(Orari!$B$6:$B$15="Vicedirettore"))>0)*(((Orari!$O$6:$O$15<=TIME(16,30,0))*(Orari!$P$6:$P$15>TIME(16,30,0)))+((Orari!$Q$6:$Q$15<=TIME(16,30,0))*(Orari!$R$6:$R$15>TIME(16,30,0))))) | J8: =SUMPRODUCT((((Orari!$B$6:$B$15="Addetto vendite")+(Orari!$B$6:$B$15="Vicedirettore"))>0)*(((Orari!$O$6:$O$15<=TIME(17,30,0))*(Orari!$P$6:$P$15>TIME(17,30,0)))+((Orari!$Q$6:$Q$15<=TIME(17,30,0))*(Orari!$R$6:$R$15>TIME(17,30,0))))) | K8: =SUMPRODUCT((((Orari!$B$6:$B$15="Addetto vendite")+(Orari!$B$6:$B$15="Vicedirettore"))>0)*(((Orari!$O$6:$O$15<=TIME(18,30,0))*(Orari!$P$6:$P$15>TIME(18,30,0)))+((Orari!$Q$6:$Q$15<=TIME(18,30,0))*(Orari!$R$6:$R$15>TIME(18,30,0))))) | L8: =SUMPRODUCT((((Orari!$B$6:$B$15="Addetto vendite")+(Orari!$B$6:$B$15="Vicedirettore"))>0)*(((Orari!$O$6:$O$15<=TIME(19,30,0))*(Orari!$P$6:$P$15>TIME(19,30,0)))+((Orari!$Q$6:$Q$15<=TIME(19,30,0))*(Orari!$R$6:$R$15>TIME(19,30,0))))) | M8: =SUMPRODUCT((((Orari!$B$6:$B$15="Addetto vendite")+(Orari!$B$6:$B$15="Vicedirettore"))>0)*(((Orari!$O$6:$O$15<=TIME(20,30,0))*(Orari!$P$6:$P$15>TIME(20,30,0)))+((Orari!$Q$6:$Q$15<=TIME(20,30,0))*(Orari!$R$6:$R$15>TIME(20,30,0)))))
A9: venerdì 16 ottobre 2026 | B9: =SUMPRODUCT((((Orari!$B$6:$B$15="Addetto vendite")+(Orari!$B$6:$B$15="Vicedirettore"))>0)*(((Orari!$S$6:$S$15<=TIME(9,30,0))*(Orari!$T$6:$T$15>TIME(9,30,0)))+((Orari!$U$6:$U$15<=TIME(9,30,0))*(Orari!$V$6:$V$15>TIME(9,30,0))))) | C9: =SUMPRODUCT((((Orari!$B$6:$B$15="Addetto vendite")+(Orari!$B$6:$B$15="Vicedirettore"))>0)*(((Orari!$S$6:$S$15<=TIME(10,30,0))*(Orari!$T$6:$T$15>TIME(10,30,0)))+((Orari!$U$6:$U$15<=TIME(10,30,0))*(Orari!$V$6:$V$15>TIME(10,30,0))))) | D9: =SUMPRODUCT((((Orari!$B$6:$B$15="Addetto vendite")+(Orari!$B$6:$B$15="Vicedirettore"))>0)*(((Orari!$S$6:$S$15<=TIME(11,30,0))*(Orari!$T$6:$T$15>TIME(11,30,0)))+((Orari!$U$6:$U$15<=TIME(11,30,0))*(Orari!$V$6:$V$15>TIME(11,30,0))))) | E9: =SUMPRODUCT((((Orari!$B$6:$B$15="Addetto vendite")+(Orari!$B$6:$B$15="Vicedirettore"))>0)*(((Orari!$S$6:$S$15<=TIME(12,30,0))*(Orari!$T$6:$T$15>TIME(12,30,0)))+((Orari!$U$6:$U$15<=TIME(12,30,0))*(Orari!$V$6:$V$15>TIME(12,30,0))))) | F9: =SUMPRODUCT((((Orari!$B$6:$B$15="Addetto vendite")+(Orari!$B$6:$B$15="Vicedirettore"))>0)*(((Orari!$S$6:$S$15<=TIME(13,30,0))*(Orari!$T$6:$T$15>TIME(13,30,0)))+((Orari!$U$6:$U$15<=TIME(13,30,0))*(Orari!$V$6:$V$15>TIME(13,30,0))))) | G9: =SUMPRODUCT((((Orari!$B$6:$B$15="Addetto vendite")+(Orari!$B$6:$B$15="Vicedirettore"))>0)*(((Orari!$S$6:$S$15<=TIME(14,30,0))*(Orari!$T$6:$T$15>TIME(14,30,0)))+((Orari!$U$6:$U$15<=TIME(14,30,0))*(Orari!$V$6:$V$15>TIME(14,30,0))))) | H9: =SUMPRODUCT((((Orari!$B$6:$B$15="Addetto vendite")+(Orari!$B$6:$B$15="Vicedirettore"))>0)*(((Orari!$S$6:$S$15<=TIME(15,30,0))*(Orari!$T$6:$T$15>TIME(15,30,0)))+((Orari!$U$6:$U$15<=TIME(15,30,0))*(Orari!$V$6:$V$15>TIME(15,30,0))))) | I9: =SUMPRODUCT((((Orari!$B$6:$B$15="Addetto vendite")+(Orari!$B$6:$B$15="Vicedirettore"))>0)*(((Orari!$S$6:$S$15<=TIME(16,30,0))*(Orari!$T$6:$T$15>TIME(16,30,0)))+((Orari!$U$6:$U$15<=TIME(16,30,0))*(Orari!$V$6:$V$15>TIME(16,30,0))))) | J9: =SUMPRODUCT((((Orari!$B$6:$B$15="Addetto vendite")+(Orari!$B$6:$B$15="Vicedirettore"))>0)*(((Orari!$S$6:$S$15<=TIME(17,30,0))*(Orari!$T$6:$T$15>TIME(17,30,0)))+((Orari!$U$6:$U$15<=TIME(17,30,0))*(Orari!$V$6:$V$15>TIME(17,30,0))))) | K9: =SUMPRODUCT((((Orari!$B$6:$B$15="Addetto vendite")+(Orari!$B$6:$B$15="Vicedirettore"))>0)*(((Orari!$S$6:$S$15<=TIME(18,30,0))*(Orari!$T$6:$T$15>TIME(18,30,0)))+((Orari!$U$6:$U$15<=TIME(18,30,0))*(Orari!$V$6:$V$15>TIME(18,30,0))))) | L9: =SUMPRODUCT((((Orari!$B$6:$B$15="Addetto vendite")+(Orari!$B$6:$B$15="Vicedirettore"))>0)*(((Orari!$S$6:$S$15<=TIME(19,30,0))*(Orari!$T$6:$T$15>TIME(19,30,0)))+((Orari!$U$6:$U$15<=TIME(19,30,0))*(Orari!$V$6:$V$15>TIME(19,30,0))))) | M9: =SUMPRODUCT((((Orari!$B$6:$B$15="Addetto vendite")+(Orari!$B$6:$B$15="Vicedirettore"))>0)*(((Orari!$S$6:$S$15<=TIME(20,30,0))*(Orari!$T$6:$T$15>TIME(20,30,0)))+((Orari!$U$6:$U$15<=TIME(20,30,0))*(Orari!$V$6:$V$15>TIME(20,30,0)))))
A10: sabato 17 ottobre 2026 | B10: =SUMPRODUCT((((Orari!$B$6:$B$15="Addetto vendite")+(Orari!$B$6:$B$15="Vicedirettore"))>0)*(((Orari!$W$6:$W$15<=TIME(9,30,0))*(Orari!$X$6:$X$15>TIME(9,30,0)))+((Orari!$Y$6:$Y$15<=TIME(9,30,0))*(Orari!$Z$6:$Z$15>TIME(9,30,0))))) | C10: =SUMPRODUCT((((Orari!$B$6:$B$15="Addetto vendite")+(Orari!$B$6:$B$15="Vicedirettore"))>0)*(((Orari!$W$6:$W$15<=TIME(10,30,0))*(Orari!$X$6:$X$15>TIME(10,30,0)))+((Orari!$Y$6:$Y$15<=TIME(10,30,0))*(Orari!$Z$6:$Z$15>TIME(10,30,0))))) | D10: =SUMPRODUCT((((Orari!$B$6:$B$15="Addetto vendite")+(Orari!$B$6:$B$15="Vicedirettore"))>0)*(((Orari!$W$6:$W$15<=TIME(11,30,0))*(Orari!$X$6:$X$15>TIME(11,30,0)))+((Orari!$Y$6:$Y$15<=TIME(11,30,0))*(Orari!$Z$6:$Z$15>TIME(11,30,0))))) | E10: =SUMPRODUCT((((Orari!$B$6:$B$15="Addetto vendite")+(Orari!$B$6:$B$15="Vicedirettore"))>0)*(((Orari!$W$6:$W$15<=TIME(12,30,0))*(Orari!$X$6:$X$15>TIME(12,30,0)))+((Orari!$Y$6:$Y$15<=TIME(12,30,0))*(Orari!$Z$6:$Z$15>TIME(12,30,0))))) | F10: =SUMPRODUCT((((Orari!$B$6:$B$15="Addetto vendite")+(Orari!$B$6:$B$15="Vicedirettore"))>0)*(((Orari!$W$6:$W$15<=TIME(13,30,0))*(Orari!$X$6:$X$15>TIME(13,30,0)))+((Orari!$Y$6:$Y$15<=TIME(13,30,0))*(Orari!$Z$6:$Z$15>TIME(13,30,0))))) | G10: =SUMPRODUCT((((Orari!$B$6:$B$15="Addetto vendite")+(Orari!$B$6:$B$15="Vicedirettore"))>0)*(((Orari!$W$6:$W$15<=TIME(14,30,0))*(Orari!$X$6:$X$15>TIME(14,30,0)))+((Orari!$Y$6:$Y$15<=TIME(14,30,0))*(Orari!$Z$6:$Z$15>TIME(14,30,0))))) | H10: =SUMPRODUCT((((Orari!$B$6:$B$15="Addetto vendite")+(Orari!$B$6:$B$15="Vicedirettore"))>0)*(((Orari!$W$6:$W$15<=TIME(15,30,0))*(Orari!$X$6:$X$15>TIME(15,30,0)))+((Orari!$Y$6:$Y$15<=TIME(15,30,0))*(Orari!$Z$6:$Z$15>TIME(15,30,0))))) | I10: =SUMPRODUCT((((Orari!$B$6:$B$15="Addetto vendite")+(Orari!$B$6:$B$15="Vicedirettore"))>0)*(((Orari!$W$6:$W$15<=TIME(16,30,0))*(Orari!$X$6:$X$15>TIME(16,30,0)))+((Orari!$Y$6:$Y$15<=TIME(16,30,0))*(Orari!$Z$6:$Z$15>TIME(16,30,0))))) | J10: =SUMPRODUCT((((Orari!$B$6:$B$15="Addetto vendite")+(Orari!$B$6:$B$15="Vicedirettore"))>0)*(((Orari!$W$6:$W$15<=TIME(17,30,0))*(Orari!$X$6:$X$15>TIME(17,30,0)))+((Orari!$Y$6:$Y$15<=TIME(17,30,0))*(Orari!$Z$6:$Z$15>TIME(17,30,0))))) | K10: =SUMPRODUCT((((Orari!$B$6:$B$15="Addetto vendite")+(Orari!$B$6:$B$15="Vicedirettore"))>0)*(((Orari!$W$6:$W$15<=TIME(18,30,0))*(Orari!$X$6:$X$15>TIME(18,30,0)))+((Orari!$Y$6:$Y$15<=TIME(18,30,0))*(Orari!$Z$6:$Z$15>TIME(18,30,0))))) | L10: =SUMPRODUCT((((Orari!$B$6:$B$15="Addetto vendite")+(Orari!$B$6:$B$15="Vicedirettore"))>0)*(((Orari!$W$6:$W$15<=TIME(19,30,0))*(Orari!$X$6:$X$15>TIME(19,30,0)))+((Orari!$Y$6:$Y$15<=TIME(19,30,0))*(Orari!$Z$6:$Z$15>TIME(19,30,0))))) | M10: =SUMPRODUCT((((Orari!$B$6:$B$15="Addetto vendite")+(Orari!$B$6:$B$15="Vicedirettore"))>0)*(((Orari!$W$6:$W$15<=TIME(20,30,0))*(Orari!$X$6:$X$15>TIME(20,30,0)))+((Orari!$Y$6:$Y$15<=TIME(20,30,0))*(Orari!$Z$6:$Z$15>TIME(20,30,0)))))
A11: domenica 18 ottobre 2026 | B11: =SUMPRODUCT((((Orari!$B$6:$B$15="Addetto vendite")+(Orari!$B$6:$B$15="Vicedirettore"))>0)*(((Orari!$AA$6:$AA$15<=TIME(9,30,0))*(Orari!$AB$6:$AB$15>TIME(9,30,0)))+((Orari!$AC$6:$AC$15<=TIME(9,30,0))*(Orari!$AD$6:$AD$15>TIME(9,30,0))))) | C11: =SUMPRODUCT((((Orari!$B$6:$B$15="Addetto vendite")+(Orari!$B$6:$B$15="Vicedirettore"))>0)*(((Orari!$AA$6:$AA$15<=TIME(10,30,0))*(Orari!$AB$6:$AB$15>TIME(10,30,0)))+((Orari!$AC$6:$AC$15<=TIME(10,30,0))*(Orari!$AD$6:$AD$15>TIME(10,30,0))))) | D11: =SUMPRODUCT((((Orari!$B$6:$B$15="Addetto vendite")+(Orari!$B$6:$B$15="Vicedirettore"))>0)*(((Orari!$AA$6:$AA$15<=TIME(11,30,0))*(Orari!$AB$6:$AB$15>TIME(11,30,0)))+((Orari!$AC$6:$AC$15<=TIME(11,30,0))*(Orari!$AD$6:$AD$15>TIME(11,30,0))))) | E11: =SUMPRODUCT((((Orari!$B$6:$B$15="Addetto vendite")+(Orari!$B$6:$B$15="Vicedirettore"))>0)*(((Orari!$AA$6:$AA$15<=TIME(12,30,0))*(Orari!$AB$6:$AB$15>TIME(12,30,0)))+((Orari!$AC$6:$AC$15<=TIME(12,30,0))*(Orari!$AD$6:$AD$15>TIME(12,30,0))))) | F11: =SUMPRODUCT((((Orari!$B$6:$B$15="Addetto vendite")+(Orari!$B$6:$B$15="Vicedirettore"))>0)*(((Orari!$AA$6:$AA$15<=TIME(13,30,0))*(Orari!$AB$6:$AB$15>TIME(13,30,0)))+((Orari!$AC$6:$AC$15<=TIME(13,30,0))*(Orari!$AD$6:$AD$15>TIME(13,30,0))))) | G11: =SUMPRODUCT((((Orari!$B$6:$B$15="Addetto vendite")+(Orari!$B$6:$B$15="Vicedirettore"))>0)*(((Orari!$AA$6:$AA$15<=TIME(14,30,0))*(Orari!$AB$6:$AB$15>TIME(14,30,0)))+((Orari!$AC$6:$AC$15<=TIME(14,30,0))*(Orari!$AD$6:$AD$15>TIME(14,30,0))))) | H11: =SUMPRODUCT((((Orari!$B$6:$B$15="Addetto vendite")+(Orari!$B$6:$B$15="Vicedirettore"))>0)*(((Orari!$AA$6:$AA$15<=TIME(15,30,0))*(Orari!$AB$6:$AB$15>TIME(15,30,0)))+((Orari!$AC$6:$AC$15<=TIME(15,30,0))*(Orari!$AD$6:$AD$15>TIME(15,30,0))))) | I11: =SUMPRODUCT((((Orari!$B$6:$B$15="Addetto vendite")+(Orari!$B$6:$B$15="Vicedirettore"))>0)*(((Orari!$AA$6:$AA$15<=TIME(16,30,0))*(Orari!$AB$6:$AB$15>TIME(16,30,0)))+((Orari!$AC$6:$AC$15<=TIME(16,30,0))*(Orari!$AD$6:$AD$15>TIME(16,30,0))))) | J11: =SUMPRODUCT((((Orari!$B$6:$B$15="Addetto vendite")+(Orari!$B$6:$B$15="Vicedirettore"))>0)*(((Orari!$AA$6:$AA$15<=TIME(17,30,0))*(Orari!$AB$6:$AB$15>TIME(17,30,0)))+((Orari!$AC$6:$AC$15<=TIME(17,30,0))*(Orari!$AD$6:$AD$15>TIME(17,30,0))))) | K11: =SUMPRODUCT((((Orari!$B$6:$B$15="Addetto vendite")+(Orari!$B$6:$B$15="Vicedirettore"))>0)*(((Orari!$AA$6:$AA$15<=TIME(18,30,0))*(Orari!$AB$6:$AB$15>TIME(18,30,0)))+((Orari!$AC$6:$AC$15<=TIME(18,30,0))*(Orari!$AD$6:$AD$15>TIME(18,30,0))))) | L11: =SUMPRODUCT((((Orari!$B$6:$B$15="Addetto vendite")+(Orari!$B$6:$B$15="Vicedirettore"))>0)*(((Orari!$AA$6:$AA$15<=TIME(19,30,0))*(Orari!$AB$6:$AB$15>TIME(19,30,0)))+((Orari!$AC$6:$AC$15<=TIME(19,30,0))*(Orari!$AD$6:$AD$15>TIME(19,30,0))))) | M11: =SUMPRODUCT((((Orari!$B$6:$B$15="Addetto vendite")+(Orari!$B$6:$B$15="Vicedirettore"))>0)*(((Orari!$AA$6:$AA$15<=TIME(20,30,0))*(Orari!$AB$6:$AB$15>TIME(20,30,0)))+((Orari!$AC$6:$AC$15<=TIME(20,30,0))*(Orari!$AD$6:$AD$15>TIME(20,30,0)))))
A13: CASSIERE — obiettivo almeno 1
A14: Giorno | B14: 9-10 | C14: 10-11 | D14: 11-12 | E14: 12-13 | F14: 13-14 | G14: 14-15 | H14: 15-16 | I14: 16-17 | J14: 17-18 | K14: 18-19 | L14: 19-20 | M14: 20-21
A15: lunedì 12 ottobre 2026 | B15: =SUMPRODUCT((Orari!$B$6:$B$15="Cassiera")*(((Orari!$C$6:$C$15<=TIME(9,30,0))*(Orari!$D$6:$D$15>TIME(9,30,0)))+((Orari!$E$6:$E$15<=TIME(9,30,0))*(Orari!$F$6:$F$15>TIME(9,30,0))))) | C15: =SUMPRODUCT((Orari!$B$6:$B$15="Cassiera")*(((Orari!$C$6:$C$15<=TIME(10,30,0))*(Orari!$D$6:$D$15>TIME(10,30,0)))+((Orari!$E$6:$E$15<=TIME(10,30,0))*(Orari!$F$6:$F$15>TIME(10,30,0))))) | D15: =SUMPRODUCT((Orari!$B$6:$B$15="Cassiera")*(((Orari!$C$6:$C$15<=TIME(11,30,0))*(Orari!$D$6:$D$15>TIME(11,30,0)))+((Orari!$E$6:$E$15<=TIME(11,30,0))*(Orari!$F$6:$F$15>TIME(11,30,0))))) | E15: =SUMPRODUCT((Orari!$B$6:$B$15="Cassiera")*(((Orari!$C$6:$C$15<=TIME(12,30,0))*(Orari!$D$6:$D$15>TIME(12,30,0)))+((Orari!$E$6:$E$15<=TIME(12,30,0))*(Orari!$F$6:$F$15>TIME(12,30,0))))) | F15: =SUMPRODUCT((Orari!$B$6:$B$15="Cassiera")*(((Orari!$C$6:$C$15<=TIME(13,30,0))*(Orari!$D$6:$D$15>TIME(13,30,0)))+((Orari!$E$6:$E$15<=TIME(13,30,0))*(Orari!$F$6:$F$15>TIME(13,30,0))))) | G15: =SUMPRODUCT((Orari!$B$6:$B$15="Cassiera")*(((Orari!$C$6:$C$15<=TIME(14,30,0))*(Orari!$D$6:$D$15>TIME(14,30,0)))+((Orari!$E$6:$E$15<=TIME(14,30,0))*(Orari!$F$6:$F$15>TIME(14,30,0))))) | H15: =SUMPRODUCT((Orari!$B$6:$B$15="Cassiera")*(((Orari!$C$6:$C$15<=TIME(15,30,0))*(Orari!$D$6:$D$15>TIME(15,30,0)))+((Orari!$E$6:$E$15<=TIME(15,30,0))*(Orari!$F$6:$F$15>TIME(15,30,0))))) | I15: =SUMPRODUCT((Orari!$B$6:$B$15="Cassiera")*(((Orari!$C$6:$C$15<=TIME(16,30,0))*(Orari!$D$6:$D$15>TIME(16,30,0)))+((Orari!$E$6:$E$15<=TIME(16,30,0))*(Orari!$F$6:$F$15>TIME(16,30,0))))) | J15: =SUMPRODUCT((Orari!$B$6:$B$15="Cassiera")*(((Orari!$C$6:$C$15<=TIME(17,30,0))*(Orari!$D$6:$D$15>TIME(17,30,0)))+((Orari!$E$6:$E$15<=TIME(17,30,0))*(Orari!$F$6:$F$15>TIME(17,30,0))))) | K15: =SUMPRODUCT((Orari!$B$6:$B$15="Cassiera")*(((Orari!$C$6:$C$15<=TIME(18,30,0))*(Orari!$D$6:$D$15>TIME(18,30,0)))+((Orari!$E$6:$E$15<=TIME(18,30,0))*(Orari!$F$6:$F$15>TIME(18,30,0))))) | L15: =SUMPRODUCT((Orari!$B$6:$B$15="Cassiera")*(((Orari!$C$6:$C$15<=TIME(19,30,0))*(Orari!$D$6:$D$15>TIME(19,30,0)))+((Orari!$E$6:$E$15<=TIME(19,30,0))*(Orari!$F$6:$F$15>TIME(19,30,0))))) | M15: =SUMPRODUCT((Orari!$B$6:$B$15="Cassiera")*(((Orari!$C$6:$C$15<=TIME(20,30,0))*(Orari!$D$6:$D$15>TIME(20,30,0)))+((Orari!$E$6:$E$15<=TIME(20,30,0))*(Orari!$F$6:$F$15>TIME(20,30,0)))))
A16: martedì 13 ottobre 2026 | B16: =SUMPRODUCT((Orari!$B$6:$B$15="Cassiera")*(((Orari!$G$6:$G$15<=TIME(9,30,0))*(Orari!$H$6:$H$15>TIME(9,30,0)))+((Orari!$I$6:$I$15<=TIME(9,30,0))*(Orari!$J$6:$J$15>TIME(9,30,0))))) | C16: =SUMPRODUCT((Orari!$B$6:$B$15="Cassiera")*(((Orari!$G$6:$G$15<=TIME(10,30,0))*(Orari!$H$6:$H$15>TIME(10,30,0)))+((Orari!$I$6:$I$15<=TIME(10,30,0))*(Orari!$J$6:$J$15>TIME(10,30,0))))) | D16: =SUMPRODUCT((Orari!$B$6:$B$15="Cassiera")*(((Orari!$G$6:$G$15<=TIME(11,30,0))*(Orari!$H$6:$H$15>TIME(11,30,0)))+((Orari!$I$6:$I$15<=TIME(11,30,0))*(Orari!$J$6:$J$15>TIME(11,30,0))))) | E16: =SUMPRODUCT((Orari!$B$6:$B$15="Cassiera")*(((Orari!$G$6:$G$15<=TIME(12,30,0))*(Orari!$H$6:$H$15>TIME(12,30,0)))+((Orari!$I$6:$I$15<=TIME(12,30,0))*(Orari!$J$6:$J$15>TIME(12,30,0))))) | F16: =SUMPRODUCT((Orari!$B$6:$B$15="Cassiera")*(((Orari!$G$6:$G$15<=TIME(13,30,0))*(Orari!$H$6:$H$15>TIME(13,30,0)))+((Orari!$I$6:$I$15<=TIME(13,30,0))*(Orari!$J$6:$J$15>TIME(13,30,0))))) | G16: =SUMPRODUCT((Orari!$B$6:$B$15="Cassiera")*(((Orari!$G$6:$G$15<=TIME(14,30,0))*(Orari!$H$6:$H$15>TIME(14,30,0)))+((Orari!$I$6:$I$15<=TIME(14,30,0))*(Orari!$J$6:$J$15>TIME(14,30,0))))) | H16: =SUMPRODUCT((Orari!$B$6:$B$15="Cassiera")*(((Orari!$G$6:$G$15<=TIME(15,30,0))*(Orari!$H$6:$H$15>TIME(15,30,0)))+((Orari!$I$6:$I$15<=TIME(15,30,0))*(Orari!$J$6:$J$15>TIME(15,30,0))))) | I16: =SUMPRODUCT((Orari!$B$6:$B$15="Cassiera")*(((Orari!$G$6:$G$15<=TIME(16,30,0))*(Orari!$H$6:$H$15>TIME(16,30,0)))+((Orari!$I$6:$I$15<=TIME(16,30,0))*(Orari!$J$6:$J$15>TIME(16,30,0))))) | J16: =SUMPRODUCT((Orari!$B$6:$B$15="Cassiera")*(((Orari!$G$6:$G$15<=TIME(17,30,0))*(Orari!$H$6:$H$15>TIME(17,30,0)))+((Orari!$I$6:$I$15<=TIME(17,30,0))*(Orari!$J$6:$J$15>TIME(17,30,0))))) | K16: =SUMPRODUCT((Orari!$B$6:$B$15="Cassiera")*(((Orari!$G$6:$G$15<=TIME(18,30,0))*(Orari!$H$6:$H$15>TIME(18,30,0)))+((Orari!$I$6:$I$15<=TIME(18,30,0))*(Orari!$J$6:$J$15>TIME(18,30,0))))) | L16: =SUMPRODUCT((Orari!$B$6:$B$15="Cassiera")*(((Orari!$G$6:$G$15<=TIME(19,30,0))*(Orari!$H$6:$H$15>TIME(19,30,0)))+((Orari!$I$6:$I$15<=TIME(19,30,0))*(Orari!$J$6:$J$15>TIME(19,30,0))))) | M16: =SUMPRODUCT((Orari!$B$6:$B$15="Cassiera")*(((Orari!$G$6:$G$15<=TIME(20,30,0))*(Orari!$H$6:$H$15>TIME(20,30,0)))+((Orari!$I$6:$I$15<=TIME(20,30,0))*(Orari!$J$6:$J$15>TIME(20,30,0)))))
A17: mercoledì 14 ottobre 2026 | B17: =SUMPRODUCT((Orari!$B$6:$B$15="Cassiera")*(((Orari!$K$6:$K$15<=TIME(9,30,0))*(Orari!$L$6:$L$15>TIME(9,30,0)))+((Orari!$M$6:$M$15<=TIME(9,30,0))*(Orari!$N$6:$N$15>TIME(9,30,0))))) | C17: =SUMPRODUCT((Orari!$B$6:$B$15="Cassiera")*(((Orari!$K$6:$K$15<=TIME(10,30,0))*(Orari!$L$6:$L$15>TIME(10,30,0)))+((Orari!$M$6:$M$15<=TIME(10,30,0))*(Orari!$N$6:$N$15>TIME(10,30,0))))) | D17: =SUMPRODUCT((Orari!$B$6:$B$15="Cassiera")*(((Orari!$K$6:$K$15<=TIME(11,30,0))*(Orari!$L$6:$L$15>TIME(11,30,0)))+((Orari!$M$6:$M$15<=TIME(11,30,0))*(Orari!$N$6:$N$15>TIME(11,30,0))))) | E17: =SUMPRODUCT((Orari!$B$6:$B$15="Cassiera")*(((Orari!$K$6:$K$15<=TIME(12,30,0))*(Orari!$L$6:$L$15>TIME(12,30,0)))+((Orari!$M$6:$M$15<=TIME(12,30,0))*(Orari!$N$6:$N$15>TIME(12,30,0))))) | F17: =SUMPRODUCT((Orari!$B$6:$B$15="Cassiera")*(((Orari!$K$6:$K$15<=TIME(13,30,0))*(Orari!$L$6:$L$15>TIME(13,30,0)))+((Orari!$M$6:$M$15<=TIME(13,30,0))*(Orari!$N$6:$N$15>TIME(13,30,0))))) | G17: =SUMPRODUCT((Orari!$B$6:$B$15="Cassiera")*(((Orari!$K$6:$K$15<=TIME(14,30,0))*(Orari!$L$6:$L$15>TIME(14,30,0)))+((Orari!$M$6:$M$15<=TIME(14,30,0))*(Orari!$N$6:$N$15>TIME(14,30,0))))) | H17: =SUMPRODUCT((Orari!$B$6:$B$15="Cassiera")*(((Orari!$K$6:$K$15<=TIME(15,30,0))*(Orari!$L$6:$L$15>TIME(15,30,0)))+((Orari!$M$6:$M$15<=TIME(15,30,0))*(Orari!$N$6:$N$15>TIME(15,30,0))))) | I17: =SUMPRODUCT((Orari!$B$6:$B$15="Cassiera")*(((Orari!$K$6:$K$15<=TIME(16,30,0))*(Orari!$L$6:$L$15>TIME(16,30,0)))+((Orari!$M$6:$M$15<=TIME(16,30,0))*(Orari!$N$6:$N$15>TIME(16,30,0))))) | J17: =SUMPRODUCT((Orari!$B$6:$B$15="Cassiera")*(((Orari!$K$6:$K$15<=TIME(17,30,0))*(Orari!$L$6:$L$15>TIME(17,30,0)))+((Orari!$M$6:$M$15<=TIME(17,30,0))*(Orari!$N$6:$N$15>TIME(17,30,0))))) | K17: =SUMPRODUCT((Orari!$B$6:$B$15="Cassiera")*(((Orari!$K$6:$K$15<=TIME(18,30,0))*(Orari!$L$6:$L$15>TIME(18,30,0)))+((Orari!$M$6:$M$15<=TIME(18,30,0))*(Orari!$N$6:$N$15>TIME(18,30,0))))) | L17: =SUMPRODUCT((Orari!$B$6:$B$15="Cassiera")*(((Orari!$K$6:$K$15<=TIME(19,30,0))*(Orari!$L$6:$L$15>TIME(19,30,0)))+((Orari!$M$6:$M$15<=TIME(19,30,0))*(Orari!$N$6:$N$15>TIME(19,30,0))))) | M17: =SUMPRODUCT((Orari!$B$6:$B$15="Cassiera")*(((Orari!$K$6:$K$15<=TIME(20,30,0))*(Orari!$L$6:$L$15>TIME(20,30,0)))+((Orari!$M$6:$M$15<=TIME(20,30,0))*(Orari!$N$6:$N$15>TIME(20,30,0)))))
A18: giovedì 15 ottobre 2026 | B18: =SUMPRODUCT((Orari!$B$6:$B$15="Cassiera")*(((Orari!$O$6:$O$15<=TIME(9,30,0))*(Orari!$P$6:$P$15>TIME(9,30,0)))+((Orari!$Q$6:$Q$15<=TIME(9,30,0))*(Orari!$R$6:$R$15>TIME(9,30,0))))) | C18: =SUMPRODUCT((Orari!$B$6:$B$15="Cassiera")*(((Orari!$O$6:$O$15<=TIME(10,30,0))*(Orari!$P$6:$P$15>TIME(10,30,0)))+((Orari!$Q$6:$Q$15<=TIME(10,30,0))*(Orari!$R$6:$R$15>TIME(10,30,0))))) | D18: =SUMPRODUCT((Orari!$B$6:$B$15="Cassiera")*(((Orari!$O$6:$O$15<=TIME(11,30,0))*(Orari!$P$6:$P$15>TIME(11,30,0)))+((Orari!$Q$6:$Q$15<=TIME(11,30,0))*(Orari!$R$6:$R$15>TIME(11,30,0))))) | E18: =SUMPRODUCT((Orari!$B$6:$B$15="Cassiera")*(((Orari!$O$6:$O$15<=TIME(12,30,0))*(Orari!$P$6:$P$15>TIME(12,30,0)))+((Orari!$Q$6:$Q$15<=TIME(12,30,0))*(Orari!$R$6:$R$15>TIME(12,30,0))))) | F18: =SUMPRODUCT((Orari!$B$6:$B$15="Cassiera")*(((Orari!$O$6:$O$15<=TIME(13,30,0))*(Orari!$P$6:$P$15>TIME(13,30,0)))+((Orari!$Q$6:$Q$15<=TIME(13,30,0))*(Orari!$R$6:$R$15>TIME(13,30,0))))) | G18: =SUMPRODUCT((Orari!$B$6:$B$15="Cassiera")*(((Orari!$O$6:$O$15<=TIME(14,30,0))*(Orari!$P$6:$P$15>TIME(14,30,0)))+((Orari!$Q$6:$Q$15<=TIME(14,30,0))*(Orari!$R$6:$R$15>TIME(14,30,0))))) | H18: =SUMPRODUCT((Orari!$B$6:$B$15="Cassiera")*(((Orari!$O$6:$O$15<=TIME(15,30,0))*(Orari!$P$6:$P$15>TIME(15,30,0)))+((Orari!$Q$6:$Q$15<=TIME(15,30,0))*(Orari!$R$6:$R$15>TIME(15,30,0))))) | I18: =SUMPRODUCT((Orari!$B$6:$B$15="Cassiera")*(((Orari!$O$6:$O$15<=TIME(16,30,0))*(Orari!$P$6:$P$15>TIME(16,30,0)))+((Orari!$Q$6:$Q$15<=TIME(16,30,0))*(Orari!$R$6:$R$15>TIME(16,30,0))))) | J18: =SUMPRODUCT((Orari!$B$6:$B$15="Cassiera")*(((Orari!$O$6:$O$15<=TIME(17,30,0))*(Orari!$P$6:$P$15>TIME(17,30,0)))+((Orari!$Q$6:$Q$15<=TIME(17,30,0))*(Orari!$R$6:$R$15>TIME(17,30,0))))) | K18: =SUMPRODUCT((Orari!$B$6:$B$15="Cassiera")*(((Orari!$O$6:$O$15<=TIME(18,30,0))*(Orari!$P$6:$P$15>TIME(18,30,0)))+((Orari!$Q$6:$Q$15<=TIME(18,30,0))*(Orari!$R$6:$R$15>TIME(18,30,0))))) | L18: =SUMPRODUCT((Orari!$B$6:$B$15="Cassiera")*(((Orari!$O$6:$O$15<=TIME(19,30,0))*(Orari!$P$6:$P$15>TIME(19,30,0)))+((Orari!$Q$6:$Q$15<=TIME(19,30,0))*(Orari!$R$6:$R$15>TIME(19,30,0))))) | M18: =SUMPRODUCT((Orari!$B$6:$B$15="Cassiera")*(((Orari!$O$6:$O$15<=TIME(20,30,0))*(Orari!$P$6:$P$15>TIME(20,30,0)))+((Orari!$Q$6:$Q$15<=TIME(20,30,0))*(Orari!$R$6:$R$15>TIME(20,30,0)))))
A19: venerdì 16 ottobre 2026 | B19: =SUMPRODUCT((Orari!$B$6:$B$15="Cassiera")*(((Orari!$S$6:$S$15<=TIME(9,30,0))*(Orari!$T$6:$T$15>TIME(9,30,0)))+((Orari!$U$6:$U$15<=TIME(9,30,0))*(Orari!$V$6:$V$15>TIME(9,30,0))))) | C19: =SUMPRODUCT((Orari!$B$6:$B$15="Cassiera")*(((Orari!$S$6:$S$15<=TIME(10,30,0))*(Orari!$T$6:$T$15>TIME(10,30,0)))+((Orari!$U$6:$U$15<=TIME(10,30,0))*(Orari!$V$6:$V$15>TIME(10,30,0))))) | D19: =SUMPRODUCT((Orari!$B$6:$B$15="Cassiera")*(((Orari!$S$6:$S$15<=TIME(11,30,0))*(Orari!$T$6:$T$15>TIME(11,30,0)))+((Orari!$U$6:$U$15<=TIME(11,30,0))*(Orari!$V$6:$V$15>TIME(11,30,0))))) | E19: =SUMPRODUCT((Orari!$B$6:$B$15="Cassiera")*(((Orari!$S$6:$S$15<=TIME(12,30,0))*(Orari!$T$6:$T$15>TIME(12,30,0)))+((Orari!$U$6:$U$15<=TIME(12,30,0))*(Orari!$V$6:$V$15>TIME(12,30,0))))) | F19: =SUMPRODUCT((Orari!$B$6:$B$15="Cassiera")*(((Orari!$S$6:$S$15<=TIME(13,30,0))*(Orari!$T$6:$T$15>TIME(13,30,0)))+((Orari!$U$6:$U$15<=TIME(13,30,0))*(Orari!$V$6:$V$15>TIME(13,30,0))))) | G19: =SUMPRODUCT((Orari!$B$6:$B$15="Cassiera")*(((Orari!$S$6:$S$15<=TIME(14,30,0))*(Orari!$T$6:$T$15>TIME(14,30,0)))+((Orari!$U$6:$U$15<=TIME(14,30,0))*(Orari!$V$6:$V$15>TIME(14,30,0))))) | H19: =SUMPRODUCT((Orari!$B$6:$B$15="Cassiera")*(((Orari!$S$6:$S$15<=TIME(15,30,0))*(Orari!$T$6:$T$15>TIME(15,30,0)))+((Orari!$U$6:$U$15<=TIME(15,30,0))*(Orari!$V$6:$V$15>TIME(15,30,0))))) | I19: =SUMPRODUCT((Orari!$B$6:$B$15="Cassiera")*(((Orari!$S$6:$S$15<=TIME(16,30,0))*(Orari!$T$6:$T$15>TIME(16,30,0)))+((Orari!$U$6:$U$15<=TIME(16,30,0))*(Orari!$V$6:$V$15>TIME(16,30,0))))) | J19: =SUMPRODUCT((Orari!$B$6:$B$15="Cassiera")*(((Orari!$S$6:$S$15<=TIME(17,30,0))*(Orari!$T$6:$T$15>TIME(17,30,0)))+((Orari!$U$6:$U$15<=TIME(17,30,0))*(Orari!$V$6:$V$15>TIME(17,30,0))))) | K19: =SUMPRODUCT((Orari!$B$6:$B$15="Cassiera")*(((Orari!$S$6:$S$15<=TIME(18,30,0))*(Orari!$T$6:$T$15>TIME(18,30,0)))+((Orari!$U$6:$U$15<=TIME(18,30,0))*(Orari!$V$6:$V$15>TIME(18,30,0))))) | L19: =SUMPRODUCT((Orari!$B$6:$B$15="Cassiera")*(((Orari!$S$6:$S$15<=TIME(19,30,0))*(Orari!$T$6:$T$15>TIME(19,30,0)))+((Orari!$U$6:$U$15<=TIME(19,30,0))*(Orari!$V$6:$V$15>TIME(19,30,0))))) | M19: =SUMPRODUCT((Orari!$B$6:$B$15="Cassiera")*(((Orari!$S$6:$S$15<=TIME(20,30,0))*(Orari!$T$6:$T$15>TIME(20,30,0)))+((Orari!$U$6:$U$15<=TIME(20,30,0))*(Orari!$V$6:$V$15>TIME(20,30,0)))))
A20: sabato 17 ottobre 2026 | B20: =SUMPRODUCT((Orari!$B$6:$B$15="Cassiera")*(((Orari!$W$6:$W$15<=TIME(9,30,0))*(Orari!$X$6:$X$15>TIME(9,30,0)))+((Orari!$Y$6:$Y$15<=TIME(9,30,0))*(Orari!$Z$6:$Z$15>TIME(9,30,0))))) | C20: =SUMPRODUCT((Orari!$B$6:$B$15="Cassiera")*(((Orari!$W$6:$W$15<=TIME(10,30,0))*(Orari!$X$6:$X$15>TIME(10,30,0)))+((Orari!$Y$6:$Y$15<=TIME(10,30,0))*(Orari!$Z$6:$Z$15>TIME(10,30,0))))) | D20: =SUMPRODUCT((Orari!$B$6:$B$15="Cassiera")*(((Orari!$W$6:$W$15<=TIME(11,30,0))*(Orari!$X$6:$X$15>TIME(11,30,0)))+((Orari!$Y$6:$Y$15<=TIME(11,30,0))*(Orari!$Z$6:$Z$15>TIME(11,30,0))))) | E20: =SUMPRODUCT((Orari!$B$6:$B$15="Cassiera")*(((Orari!$W$6:$W$15<=TIME(12,30,0))*(Orari!$X$6:$X$15>TIME(12,30,0)))+((Orari!$Y$6:$Y$15<=TIME(12,30,0))*(Orari!$Z$6:$Z$15>TIME(12,30,0))))) | F20: =SUMPRODUCT((Orari!$B$6:$B$15="Cassiera")*(((Orari!$W$6:$W$15<=TIME(13,30,0))*(Orari!$X$6:$X$15>TIME(13,30,0)))+((Orari!$Y$6:$Y$15<=TIME(13,30,0))*(Orari!$Z$6:$Z$15>TIME(13,30,0))))) | G20: =SUMPRODUCT((Orari!$B$6:$B$15="Cassiera")*(((Orari!$W$6:$W$15<=TIME(14,30,0))*(Orari!$X$6:$X$15>TIME(14,30,0)))+((Orari!$Y$6:$Y$15<=TIME(14,30,0))*(Orari!$Z$6:$Z$15>TIME(14,30,0))))) | H20: =SUMPRODUCT((Orari!$B$6:$B$15="Cassiera")*(((Orari!$W$6:$W$15<=TIME(15,30,0))*(Orari!$X$6:$X$15>TIME(15,30,0)))+((Orari!$Y$6:$Y$15<=TIME(15,30,0))*(Orari!$Z$6:$Z$15>TIME(15,30,0))))) | I20: =SUMPRODUCT((Orari!$B$6:$B$15="Cassiera")*(((Orari!$W$6:$W$15<=TIME(16,30,0))*(Orari!$X$6:$X$15>TIME(16,30,0)))+((Orari!$Y$6:$Y$15<=TIME(16,30,0))*(Orari!$Z$6:$Z$15>TIME(16,30,0))))) | J20: =SUMPRODUCT((Orari!$B$6:$B$15="Cassiera")*(((Orari!$W$6:$W$15<=TIME(17,30,0))*(Orari!$X$6:$X$15>TIME(17,30,0)))+((Orari!$Y$6:$Y$15<=TIME(17,30,0))*(Orari!$Z$6:$Z$15>TIME(17,30,0))))) | K20: =SUMPRODUCT((Orari!$B$6:$B$15="Cassiera")*(((Orari!$W$6:$W$15<=TIME(18,30,0))*(Orari!$X$6:$X$15>TIME(18,30,0)))+((Orari!$Y$6:$Y$15<=TIME(18,30,0))*(Orari!$Z$6:$Z$15>TIME(18,30,0))))) | L20: =SUMPRODUCT((Orari!$B$6:$B$15="Cassiera")*(((Orari!$W$6:$W$15<=TIME(19,30,0))*(Orari!$X$6:$X$15>TIME(19,30,0)))+((Orari!$Y$6:$Y$15<=TIME(19,30,0))*(Orari!$Z$6:$Z$15>TIME(19,30,0))))) | M20: =SUMPRODUCT((Orari!$B$6:$B$15="Cassiera")*(((Orari!$W$6:$W$15<=TIME(20,30,0))*(Orari!$X$6:$X$15>TIME(20,30,0)))+((Orari!$Y$6:$Y$15<=TIME(20,30,0))*(Orari!$Z$6:$Z$15>TIME(20,30,0)))))
A21: domenica 18 ottobre 2026 | B21: =SUMPRODUCT((Orari!$B$6:$B$15="Cassiera")*(((Orari!$AA$6:$AA$15<=TIME(9,30,0))*(Orari!$AB$6:$AB$15>TIME(9,30,0)))+((Orari!$AC$6:$AC$15<=TIME(9,30,0))*(Orari!$AD$6:$AD$15>TIME(9,30,0))))) | C21: =SUMPRODUCT((Orari!$B$6:$B$15="Cassiera")*(((Orari!$AA$6:$AA$15<=TIME(10,30,0))*(Orari!$AB$6:$AB$15>TIME(10,30,0)))+((Orari!$AC$6:$AC$15<=TIME(10,30,0))*(Orari!$AD$6:$AD$15>TIME(10,30,0))))) | D21: =SUMPRODUCT((Orari!$B$6:$B$15="Cassiera")*(((Orari!$AA$6:$AA$15<=TIME(11,30,0))*(Orari!$AB$6:$AB$15>TIME(11,30,0)))+((Orari!$AC$6:$AC$15<=TIME(11,30,0))*(Orari!$AD$6:$AD$15>TIME(11,30,0))))) | E21: =SUMPRODUCT((Orari!$B$6:$B$15="Cassiera")*(((Orari!$AA$6:$AA$15<=TIME(12,30,0))*(Orari!$AB$6:$AB$15>TIME(12,30,0)))+((Orari!$AC$6:$AC$15<=TIME(12,30,0))*(Orari!$AD$6:$AD$15>TIME(12,30,0))))) | F21: =SUMPRODUCT((Orari!$B$6:$B$15="Cassiera")*(((Orari!$AA$6:$AA$15<=TIME(13,30,0))*(Orari!$AB$6:$AB$15>TIME(13,30,0)))+((Orari!$AC$6:$AC$15<=TIME(13,30,0))*(Orari!$AD$6:$AD$15>TIME(13,30,0))))) | G21: =SUMPRODUCT((Orari!$B$6:$B$15="Cassiera")*(((Orari!$AA$6:$AA$15<=TIME(14,30,0))*(Orari!$AB$6:$AB$15>TIME(14,30,0)))+((Orari!$AC$6:$AC$15<=TIME(14,30,0))*(Orari!$AD$6:$AD$15>TIME(14,30,0))))) | H21: =SUMPRODUCT((Orari!$B$6:$B$15="Cassiera")*(((Orari!$AA$6:$AA$15<=TIME(15,30,0))*(Orari!$AB$6:$AB$15>TIME(15,30,0)))+((Orari!$AC$6:$AC$15<=TIME(15,30,0))*(Orari!$AD$6:$AD$15>TIME(15,30,0))))) | I21: =SUMPRODUCT((Orari!$B$6:$B$15="Cassiera")*(((Orari!$AA$6:$AA$15<=TIME(16,30,0))*(Orari!$AB$6:$AB$15>TIME(16,30,0)))+((Orari!$AC$6:$AC$15<=TIME(16,30,0))*(Orari!$AD$6:$AD$15>TIME(16,30,0))))) | J21: =SUMPRODUCT((Orari!$B$6:$B$15="Cassiera")*(((Orari!$AA$6:$AA$15<=TIME(17,30,0))*(Orari!$AB$6:$AB$15>TIME(17,30,0)))+((Orari!$AC$6:$AC$15<=TIME(17,30,0))*(Orari!$AD$6:$AD$15>TIME(17,30,0))))) | K21: =SUMPRODUCT((Orari!$B$6:$B$15="Cassiera")*(((Orari!$AA$6:$AA$15<=TIME(18,30,0))*(Orari!$AB$6:$AB$15>TIME(18,30,0)))+((Orari!$AC$6:$AC$15<=TIME(18,30,0))*(Orari!$AD$6:$AD$15>TIME(18,30,0))))) | L21: =SUMPRODUCT((Orari!$B$6:$B$15="Cassiera")*(((Orari!$AA$6:$AA$15<=TIME(19,30,0))*(Orari!$AB$6:$AB$15>TIME(19,30,0)))+((Orari!$AC$6:$AC$15<=TIME(19,30,0))*(Orari!$AD$6:$AD$15>TIME(19,30,0))))) | M21: =SUMPRODUCT((Orari!$B$6:$B$15="Cassiera")*(((Orari!$AA$6:$AA$15<=TIME(20,30,0))*(Orari!$AB$6:$AB$15>TIME(20,30,0)))+((Orari!$AC$6:$AC$15<=TIME(20,30,0))*(Orari!$AD$6:$AD$15>TIME(20,30,0)))))
A23: PERSONE CON LE CHIAVI — obiettivo almeno 1
A24: Giorno | B24: 9-10 | C24: 10-11 | D24: 11-12 | E24: 12-13 | F24: 13-14 | G24: 14-15 | H24: 15-16 | I24: 16-17 | J24: 17-18 | K24: 18-19 | L24: 19-20 | M24: 20-21
A25: lunedì 12 ottobre 2026 | B25: =SUMPRODUCT((ISNUMBER(SEARCH("🔑",Orari!$A$6:$A$15)))*(((Orari!$C$6:$C$15<=TIME(9,30,0))*(Orari!$D$6:$D$15>TIME(9,30,0)))+((Orari!$E$6:$E$15<=TIME(9,30,0))*(Orari!$F$6:$F$15>TIME(9,30,0))))) | C25: =SUMPRODUCT((ISNUMBER(SEARCH("🔑",Orari!$A$6:$A$15)))*(((Orari!$C$6:$C$15<=TIME(10,30,0))*(Orari!$D$6:$D$15>TIME(10,30,0)))+((Orari!$E$6:$E$15<=TIME(10,30,0))*(Orari!$F$6:$F$15>TIME(10,30,0))))) | D25: =SUMPRODUCT((ISNUMBER(SEARCH("🔑",Orari!$A$6:$A$15)))*(((Orari!$C$6:$C$15<=TIME(11,30,0))*(Orari!$D$6:$D$15>TIME(11,30,0)))+((Orari!$E$6:$E$15<=TIME(11,30,0))*(Orari!$F$6:$F$15>TIME(11,30,0))))) | E25: =SUMPRODUCT((ISNUMBER(SEARCH("🔑",Orari!$A$6:$A$15)))*(((Orari!$C$6:$C$15<=TIME(12,30,0))*(Orari!$D$6:$D$15>TIME(12,30,0)))+((Orari!$E$6:$E$15<=TIME(12,30,0))*(Orari!$F$6:$F$15>TIME(12,30,0))))) | F25: =SUMPRODUCT((ISNUMBER(SEARCH("🔑",Orari!$A$6:$A$15)))*(((Orari!$C$6:$C$15<=TIME(13,30,0))*(Orari!$D$6:$D$15>TIME(13,30,0)))+((Orari!$E$6:$E$15<=TIME(13,30,0))*(Orari!$F$6:$F$15>TIME(13,30,0))))) | G25: =SUMPRODUCT((ISNUMBER(SEARCH("🔑",Orari!$A$6:$A$15)))*(((Orari!$C$6:$C$15<=TIME(14,30,0))*(Orari!$D$6:$D$15>TIME(14,30,0)))+((Orari!$E$6:$E$15<=TIME(14,30,0))*(Orari!$F$6:$F$15>TIME(14,30,0))))) | H25: =SUMPRODUCT((ISNUMBER(SEARCH("🔑",Orari!$A$6:$A$15)))*(((Orari!$C$6:$C$15<=TIME(15,30,0))*(Orari!$D$6:$D$15>TIME(15,30,0)))+((Orari!$E$6:$E$15<=TIME(15,30,0))*(Orari!$F$6:$F$15>TIME(15,30,0))))) | I25: =SUMPRODUCT((ISNUMBER(SEARCH("🔑",Orari!$A$6:$A$15)))*(((Orari!$C$6:$C$15<=TIME(16,30,0))*(Orari!$D$6:$D$15>TIME(16,30,0)))+((Orari!$E$6:$E$15<=TIME(16,30,0))*(Orari!$F$6:$F$15>TIME(16,30,0))))) | J25: =SUMPRODUCT((ISNUMBER(SEARCH("🔑",Orari!$A$6:$A$15)))*(((Orari!$C$6:$C$15<=TIME(17,30,0))*(Orari!$D$6:$D$15>TIME(17,30,0)))+((Orari!$E$6:$E$15<=TIME(17,30,0))*(Orari!$F$6:$F$15>TIME(17,30,0))))) | K25: =SUMPRODUCT((ISNUMBER(SEARCH("🔑",Orari!$A$6:$A$15)))*(((Orari!$C$6:$C$15<=TIME(18,30,0))*(Orari!$D$6:$D$15>TIME(18,30,0)))+((Orari!$E$6:$E$15<=TIME(18,30,0))*(Orari!$F$6:$F$15>TIME(18,30,0))))) | L25: =SUMPRODUCT((ISNUMBER(SEARCH("🔑",Orari!$A$6:$A$15)))*(((Orari!$C$6:$C$15<=TIME(19,30,0))*(Orari!$D$6:$D$15>TIME(19,30,0)))+((Orari!$E$6:$E$15<=TIME(19,30,0))*(Orari!$F$6:$F$15>TIME(19,30,0))))) | M25: =SUMPRODUCT((ISNUMBER(SEARCH("🔑",Orari!$A$6:$A$15)))*(((Orari!$C$6:$C$15<=TIME(20,30,0))*(Orari!$D$6:$D$15>TIME(20,30,0)))+((Orari!$E$6:$E$15<=TIME(20,30,0))*(Orari!$F$6:$F$15>TIME(20,30,0)))))
A26: martedì 13 ottobre 2026 | B26: =SUMPRODUCT((ISNUMBER(SEARCH("🔑",Orari!$A$6:$A$15)))*(((Orari!$G$6:$G$15<=TIME(9,30,0))*(Orari!$H$6:$H$15>TIME(9,30,0)))+((Orari!$I$6:$I$15<=TIME(9,30,0))*(Orari!$J$6:$J$15>TIME(9,30,0))))) | C26: =SUMPRODUCT((ISNUMBER(SEARCH("🔑",Orari!$A$6:$A$15)))*(((Orari!$G$6:$G$15<=TIME(10,30,0))*(Orari!$H$6:$H$15>TIME(10,30,0)))+((Orari!$I$6:$I$15<=TIME(10,30,0))*(Orari!$J$6:$J$15>TIME(10,30,0))))) | D26: =SUMPRODUCT((ISNUMBER(SEARCH("🔑",Orari!$A$6:$A$15)))*(((Orari!$G$6:$G$15<=TIME(11,30,0))*(Orari!$H$6:$H$15>TIME(11,30,0)))+((Orari!$I$6:$I$15<=TIME(11,30,0))*(Orari!$J$6:$J$15>TIME(11,30,0))))) | E26: =SUMPRODUCT((ISNUMBER(SEARCH("🔑",Orari!$A$6:$A$15)))*(((Orari!$G$6:$G$15<=TIME(12,30,0))*(Orari!$H$6:$H$15>TIME(12,30,0)))+((Orari!$I$6:$I$15<=TIME(12,30,0))*(Orari!$J$6:$J$15>TIME(12,30,0))))) | F26: =SUMPRODUCT((ISNUMBER(SEARCH("🔑",Orari!$A$6:$A$15)))*(((Orari!$G$6:$G$15<=TIME(13,30,0))*(Orari!$H$6:$H$15>TIME(13,30,0)))+((Orari!$I$6:$I$15<=TIME(13,30,0))*(Orari!$J$6:$J$15>TIME(13,30,0))))) | G26: =SUMPRODUCT((ISNUMBER(SEARCH("🔑",Orari!$A$6:$A$15)))*(((Orari!$G$6:$G$15<=TIME(14,30,0))*(Orari!$H$6:$H$15>TIME(14,30,0)))+((Orari!$I$6:$I$15<=TIME(14,30,0))*(Orari!$J$6:$J$15>TIME(14,30,0))))) | H26: =SUMPRODUCT((ISNUMBER(SEARCH("🔑",Orari!$A$6:$A$15)))*(((Orari!$G$6:$G$15<=TIME(15,30,0))*(Orari!$H$6:$H$15>TIME(15,30,0)))+((Orari!$I$6:$I$15<=TIME(15,30,0))*(Orari!$J$6:$J$15>TIME(15,30,0))))) | I26: =SUMPRODUCT((ISNUMBER(SEARCH("🔑",Orari!$A$6:$A$15)))*(((Orari!$G$6:$G$15<=TIME(16,30,0))*(Orari!$H$6:$H$15>TIME(16,30,0)))+((Orari!$I$6:$I$15<=TIME(16,30,0))*(Orari!$J$6:$J$15>TIME(16,30,0))))) | J26: =SUMPRODUCT((ISNUMBER(SEARCH("🔑",Orari!$A$6:$A$15)))*(((Orari!$G$6:$G$15<=TIME(17,30,0))*(Orari!$H$6:$H$15>TIME(17,30,0)))+((Orari!$I$6:$I$15<=TIME(17,30,0))*(Orari!$J$6:$J$15>TIME(17,30,0))))) | K26: =SUMPRODUCT((ISNUMBER(SEARCH("🔑",Orari!$A$6:$A$15)))*(((Orari!$G$6:$G$15<=TIME(18,30,0))*(Orari!$H$6:$H$15>TIME(18,30,0)))+((Orari!$I$6:$I$15<=TIME(18,30,0))*(Orari!$J$6:$J$15>TIME(18,30,0))))) | L26: =SUMPRODUCT((ISNUMBER(SEARCH("🔑",Orari!$A$6:$A$15)))*(((Orari!$G$6:$G$15<=TIME(19,30,0))*(Orari!$H$6:$H$15>TIME(19,30,0)))+((Orari!$I$6:$I$15<=TIME(19,30,0))*(Orari!$J$6:$J$15>TIME(19,30,0))))) | M26: =SUMPRODUCT((ISNUMBER(SEARCH("🔑",Orari!$A$6:$A$15)))*(((Orari!$G$6:$G$15<=TIME(20,30,0))*(Orari!$H$6:$H$15>TIME(20,30,0)))+((Orari!$I$6:$I$15<=TIME(20,30,0))*(Orari!$J$6:$J$15>TIME(20,30,0)))))
A27: mercoledì 14 ottobre 2026 | B27: =SUMPRODUCT((ISNUMBER(SEARCH("🔑",Orari!$A$6:$A$15)))*(((Orari!$K$6:$K$15<=TIME(9,30,0))*(Orari!$L$6:$L$15>TIME(9,30,0)))+((Orari!$M$6:$M$15<=TIME(9,30,0))*(Orari!$N$6:$N$15>TIME(9,30,0))))) | C27: =SUMPRODUCT((ISNUMBER(SEARCH("🔑",Orari!$A$6:$A$15)))*(((Orari!$K$6:$K$15<=TIME(10,30,0))*(Orari!$L$6:$L$15>TIME(10,30,0)))+((Orari!$M$6:$M$15<=TIME(10,30,0))*(Orari!$N$6:$N$15>TIME(10,30,0))))) | D27: =SUMPRODUCT((ISNUMBER(SEARCH("🔑",Orari!$A$6:$A$15)))*(((Orari!$K$6:$K$15<=TIME(11,30,0))*(Orari!$L$6:$L$15>TIME(11,30,0)))+((Orari!$M$6:$M$15<=TIME(11,30,0))*(Orari!$N$6:$N$15>TIME(11,30,0))))) | E27: =SUMPRODUCT((ISNUMBER(SEARCH("🔑",Orari!$A$6:$A$15)))*(((Orari!$K$6:$K$15<=TIME(12,30,0))*(Orari!$L$6:$L$15>TIME(12,30,0)))+((Orari!$M$6:$M$15<=TIME(12,30,0))*(Orari!$N$6:$N$15>TIME(12,30,0))))) | F27: =SUMPRODUCT((ISNUMBER(SEARCH("🔑",Orari!$A$6:$A$15)))*(((Orari!$K$6:$K$15<=TIME(13,30,0))*(Orari!$L$6:$L$15>TIME(13,30,0)))+((Orari!$M$6:$M$15<=TIME(13,30,0))*(Orari!$N$6:$N$15>TIME(13,30,0))))) | G27: =SUMPRODUCT((ISNUMBER(SEARCH("🔑",Orari!$A$6:$A$15)))*(((Orari!$K$6:$K$15<=TIME(14,30,0))*(Orari!$L$6:$L$15>TIME(14,30,0)))+((Orari!$M$6:$M$15<=TIME(14,30,0))*(Orari!$N$6:$N$15>TIME(14,30,0))))) | H27: =SUMPRODUCT((ISNUMBER(SEARCH("🔑",Orari!$A$6:$A$15)))*(((Orari!$K$6:$K$15<=TIME(15,30,0))*(Orari!$L$6:$L$15>TIME(15,30,0)))+((Orari!$M$6:$M$15<=TIME(15,30,0))*(Orari!$N$6:$N$15>TIME(15,30,0))))) | I27: =SUMPRODUCT((ISNUMBER(SEARCH("🔑",Orari!$A$6:$A$15)))*(((Orari!$K$6:$K$15<=TIME(16,30,0))*(Orari!$L$6:$L$15>TIME(16,30,0)))+((Orari!$M$6:$M$15<=TIME(16,30,0))*(Orari!$N$6:$N$15>TIME(16,30,0))))) | J27: =SUMPRODUCT((ISNUMBER(SEARCH("🔑",Orari!$A$6:$A$15)))*(((Orari!$K$6:$K$15<=TIME(17,30,0))*(Orari!$L$6:$L$15>TIME(17,30,0)))+((Orari!$M$6:$M$15<=TIME(17,30,0))*(Orari!$N$6:$N$15>TIME(17,30,0))))) | K27: =SUMPRODUCT((ISNUMBER(SEARCH("🔑",Orari!$A$6:$A$15)))*(((Orari!$K$6:$K$15<=TIME(18,30,0))*(Orari!$L$6:$L$15>TIME(18,30,0)))+((Orari!$M$6:$M$15<=TIME(18,30,0))*(Orari!$N$6:$N$15>TIME(18,30,0))))) | L27: =SUMPRODUCT((ISNUMBER(SEARCH("🔑",Orari!$A$6:$A$15)))*(((Orari!$K$6:$K$15<=TIME(19,30,0))*(Orari!$L$6:$L$15>TIME(19,30,0)))+((Orari!$M$6:$M$15<=TIME(19,30,0))*(Orari!$N$6:$N$15>TIME(19,30,0))))) | M27: =SUMPRODUCT((ISNUMBER(SEARCH("🔑",Orari!$A$6:$A$15)))*(((Orari!$K$6:$K$15<=TIME(20,30,0))*(Orari!$L$6:$L$15>TIME(20,30,0)))+((Orari!$M$6:$M$15<=TIME(20,30,0))*(Orari!$N$6:$N$15>TIME(20,30,0)))))
A28: giovedì 15 ottobre 2026 | B28: =SUMPRODUCT((ISNUMBER(SEARCH("🔑",Orari!$A$6:$A$15)))*(((Orari!$O$6:$O$15<=TIME(9,30,0))*(Orari!$P$6:$P$15>TIME(9,30,0)))+((Orari!$Q$6:$Q$15<=TIME(9,30,0))*(Orari!$R$6:$R$15>TIME(9,30,0))))) | C28: =SUMPRODUCT((ISNUMBER(SEARCH("🔑",Orari!$A$6:$A$15)))*(((Orari!$O$6:$O$15<=TIME(10,30,0))*(Orari!$P$6:$P$15>TIME(10,30,0)))+((Orari!$Q$6:$Q$15<=TIME(10,30,0))*(Orari!$R$6:$R$15>TIME(10,30,0))))) | D28: =SUMPRODUCT((ISNUMBER(SEARCH("🔑",Orari!$A$6:$A$15)))*(((Orari!$O$6:$O$15<=TIME(11,30,0))*(Orari!$P$6:$P$15>TIME(11,30,0)))+((Orari!$Q$6:$Q$15<=TIME(11,30,0))*(Orari!$R$6:$R$15>TIME(11,30,0))))) | E28: =SUMPRODUCT((ISNUMBER(SEARCH("🔑",Orari!$A$6:$A$15)))*(((Orari!$O$6:$O$15<=TIME(12,30,0))*(Orari!$P$6:$P$15>TIME(12,30,0)))+((Orari!$Q$6:$Q$15<=TIME(12,30,0))*(Orari!$R$6:$R$15>TIME(12,30,0))))) | F28: =SUMPRODUCT((ISNUMBER(SEARCH("🔑",Orari!$A$6:$A$15)))*(((Orari!$O$6:$O$15<=TIME(13,30,0))*(Orari!$P$6:$P$15>TIME(13,30,0)))+((Orari!$Q$6:$Q$15<=TIME(13,30,0))*(Orari!$R$6:$R$15>TIME(13,30,0))))) | G28: =SUMPRODUCT((ISNUMBER(SEARCH("🔑",Orari!$A$6:$A$15)))*(((Orari!$O$6:$O$15<=TIME(14,30,0))*(Orari!$P$6:$P$15>TIME(14,30,0)))+((Orari!$Q$6:$Q$15<=TIME(14,30,0))*(Orari!$R$6:$R$15>TIME(14,30,0))))) | H28: =SUMPRODUCT((ISNUMBER(SEARCH("🔑",Orari!$A$6:$A$15)))*(((Orari!$O$6:$O$15<=TIME(15,30,0))*(Orari!$P$6:$P$15>TIME(15,30,0)))+((Orari!$Q$6:$Q$15<=TIME(15,30,0))*(Orari!$R$6:$R$15>TIME(15,30,0))))) | I28: =SUMPRODUCT((ISNUMBER(SEARCH("🔑",Orari!$A$6:$A$15)))*(((Orari!$O$6:$O$15<=TIME(16,30,0))*(Orari!$P$6:$P$15>TIME(16,30,0)))+((Orari!$Q$6:$Q$15<=TIME(16,30,0))*(Orari!$R$6:$R$15>TIME(16,30,0))))) | J28: =SUMPRODUCT((ISNUMBER(SEARCH("🔑",Orari!$A$6:$A$15)))*(((Orari!$O$6:$O$15<=TIME(17,30,0))*(Orari!$P$6:$P$15>TIME(17,30,0)))+((Orari!$Q$6:$Q$15<=TIME(17,30,0))*(Orari!$R$6:$R$15>TIME(17,30,0))))) | K28: =SUMPRODUCT((ISNUMBER(SEARCH("🔑",Orari!$A$6:$A$15)))*(((Orari!$O$6:$O$15<=TIME(18,30,0))*(Orari!$P$6:$P$15>TIME(18,30,0)))+((Orari!$Q$6:$Q$15<=TIME(18,30,0))*(Orari!$R$6:$R$15>TIME(18,30,0))))) | L28: =SUMPRODUCT((ISNUMBER(SEARCH("🔑",Orari!$A$6:$A$15)))*(((Orari!$O$6:$O$15<=TIME(19,30,0))*(Orari!$P$6:$P$15>TIME(19,30,0)))+((Orari!$Q$6:$Q$15<=TIME(19,30,0))*(Orari!$R$6:$R$15>TIME(19,30,0))))) | M28: =SUMPRODUCT((ISNUMBER(SEARCH("🔑",Orari!$A$6:$A$15)))*(((Orari!$O$6:$O$15<=TIME(20,30,0))*(Orari!$P$6:$P$15>TIME(20,30,0)))+((Orari!$Q$6:$Q$15<=TIME(20,30,0))*(Orari!$R$6:$R$15>TIME(20,30,0)))))
A29: venerdì 16 ottobre 2026 | B29: =SUMPRODUCT((ISNUMBER(SEARCH("🔑",Orari!$A$6:$A$15)))*(((Orari!$S$6:$S$15<=TIME(9,30,0))*(Orari!$T$6:$T$15>TIME(9,30,0)))+((Orari!$U$6:$U$15<=TIME(9,30,0))*(Orari!$V$6:$V$15>TIME(9,30,0))))) | C29: =SUMPRODUCT((ISNUMBER(SEARCH("🔑",Orari!$A$6:$A$15)))*(((Orari!$S$6:$S$15<=TIME(10,30,0))*(Orari!$T$6:$T$15>TIME(10,30,0)))+((Orari!$U$6:$U$15<=TIME(10,30,0))*(Orari!$V$6:$V$15>TIME(10,30,0))))) | D29: =SUMPRODUCT((ISNUMBER(SEARCH("🔑",Orari!$A$6:$A$15)))*(((Orari!$S$6:$S$15<=TIME(11,30,0))*(Orari!$T$6:$T$15>TIME(11,30,0)))+((Orari!$U$6:$U$15<=TIME(11,30,0))*(Orari!$V$6:$V$15>TIME(11,30,0))))) | E29: =SUMPRODUCT((ISNUMBER(SEARCH("🔑",Orari!$A$6:$A$15)))*(((Orari!$S$6:$S$15<=TIME(12,30,0))*(Orari!$T$6:$T$15>TIME(12,30,0)))+((Orari!$U$6:$U$15<=TIME(12,30,0))*(Orari!$V$6:$V$15>TIME(12,30,0))))) | F29: =SUMPRODUCT((ISNUMBER(SEARCH("🔑",Orari!$A$6:$A$15)))*(((Orari!$S$6:$S$15<=TIME(13,30,0))*(Orari!$T$6:$T$15>TIME(13,30,0)))+((Orari!$U$6:$U$15<=TIME(13,30,0))*(Orari!$V$6:$V$15>TIME(13,30,0))))) | G29: =SUMPRODUCT((ISNUMBER(SEARCH("🔑",Orari!$A$6:$A$15)))*(((Orari!$S$6:$S$15<=TIME(14,30,0))*(Orari!$T$6:$T$15>TIME(14,30,0)))+((Orari!$U$6:$U$15<=TIME(14,30,0))*(Orari!$V$6:$V$15>TIME(14,30,0))))) | H29: =SUMPRODUCT((ISNUMBER(SEARCH("🔑",Orari!$A$6:$A$15)))*(((Orari!$S$6:$S$15<=TIME(15,30,0))*(Orari!$T$6:$T$15>TIME(15,30,0)))+((Orari!$U$6:$U$15<=TIME(15,30,0))*(Orari!$V$6:$V$15>TIME(15,30,0))))) | I29: =SUMPRODUCT((ISNUMBER(SEARCH("🔑",Orari!$A$6:$A$15)))*(((Orari!$S$6:$S$15<=TIME(16,30,0))*(Orari!$T$6:$T$15>TIME(16,30,0)))+((Orari!$U$6:$U$15<=TIME(16,30,0))*(Orari!$V$6:$V$15>TIME(16,30,0))))) | J29: =SUMPRODUCT((ISNUMBER(SEARCH("🔑",Orari!$A$6:$A$15)))*(((Orari!$S$6:$S$15<=TIME(17,30,0))*(Orari!$T$6:$T$15>TIME(17,30,0)))+((Orari!$U$6:$U$15<=TIME(17,30,0))*(Orari!$V$6:$V$15>TIME(17,30,0))))) | K29: =SUMPRODUCT((ISNUMBER(SEARCH("🔑",Orari!$A$6:$A$15)))*(((Orari!$S$6:$S$15<=TIME(18,30,0))*(Orari!$T$6:$T$15>TIME(18,30,0)))+((Orari!$U$6:$U$15<=TIME(18,30,0))*(Orari!$V$6:$V$15>TIME(18,30,0))))) | L29: =SUMPRODUCT((ISNUMBER(SEARCH("🔑",Orari!$A$6:$A$15)))*(((Orari!$S$6:$S$15<=TIME(19,30,0))*(Orari!$T$6:$T$15>TIME(19,30,0)))+((Orari!$U$6:$U$15<=TIME(19,30,0))*(Orari!$V$6:$V$15>TIME(19,30,0))))) | M29: =SUMPRODUCT((ISNUMBER(SEARCH("🔑",Orari!$A$6:$A$15)))*(((Orari!$S$6:$S$15<=TIME(20,30,0))*(Orari!$T$6:$T$15>TIME(20,30,0)))+((Orari!$U$6:$U$15<=TIME(20,30,0))*(Orari!$V$6:$V$15>TIME(20,30,0)))))
A30: sabato 17 ottobre 2026 | B30: =SUMPRODUCT((ISNUMBER(SEARCH("🔑",Orari!$A$6:$A$15)))*(((Orari!$W$6:$W$15<=TIME(9,30,0))*(Orari!$X$6:$X$15>TIME(9,30,0)))+((Orari!$Y$6:$Y$15<=TIME(9,30,0))*(Orari!$Z$6:$Z$15>TIME(9,30,0))))) | C30: =SUMPRODUCT((ISNUMBER(SEARCH("🔑",Orari!$A$6:$A$15)))*(((Orari!$W$6:$W$15<=TIME(10,30,0))*(Orari!$X$6:$X$15>TIME(10,30,0)))+((Orari!$Y$6:$Y$15<=TIME(10,30,0))*(Orari!$Z$6:$Z$15>TIME(10,30,0))))) | D30: =SUMPRODUCT((ISNUMBER(SEARCH("🔑",Orari!$A$6:$A$15)))*(((Orari!$W$6:$W$15<=TIME(11,30,0))*(Orari!$X$6:$X$15>TIME(11,30,0)))+((Orari!$Y$6:$Y$15<=TIME(11,30,0))*(Orari!$Z$6:$Z$15>TIME(11,30,0))))) | E30: =SUMPRODUCT((ISNUMBER(SEARCH("🔑",Orari!$A$6:$A$15)))*(((Orari!$W$6:$W$15<=TIME(12,30,0))*(Orari!$X$6:$X$15>TIME(12,30,0)))+((Orari!$Y$6:$Y$15<=TIME(12,30,0))*(Orari!$Z$6:$Z$15>TIME(12,30,0))))) | F30: =SUMPRODUCT((ISNUMBER(SEARCH("🔑",Orari!$A$6:$A$15)))*(((Orari!$W$6:$W$15<=TIME(13,30,0))*(Orari!$X$6:$X$15>TIME(13,30,0)))+((Orari!$Y$6:$Y$15<=TIME(13,30,0))*(Orari!$Z$6:$Z$15>TIME(13,30,0))))) | G30: =SUMPRODUCT((ISNUMBER(SEARCH("🔑",Orari!$A$6:$A$15)))*(((Orari!$W$6:$W$15<=TIME(14,30,0))*(Orari!$X$6:$X$15>TIME(14,30,0)))+((Orari!$Y$6:$Y$15<=TIME(14,30,0))*(Orari!$Z$6:$Z$15>TIME(14,30,0))))) | H30: =SUMPRODUCT((ISNUMBER(SEARCH("🔑",Orari!$A$6:$A$15)))*(((Orari!$W$6:$W$15<=TIME(15,30,0))*(Orari!$X$6:$X$15>TIME(15,30,0)))+((Orari!$Y$6:$Y$15<=TIME(15,30,0))*(Orari!$Z$6:$Z$15>TIME(15,30,0))))) | I30: =SUMPRODUCT((ISNUMBER(SEARCH("🔑",Orari!$A$6:$A$15)))*(((Orari!$W$6:$W$15<=TIME(16,30,0))*(Orari!$X$6:$X$15>TIME(16,30,0)))+((Orari!$Y$6:$Y$15<=TIME(16,30,0))*(Orari!$Z$6:$Z$15>TIME(16,30,0))))) | J30: =SUMPRODUCT((ISNUMBER(SEARCH("🔑",Orari!$A$6:$A$15)))*(((Orari!$W$6:$W$15<=TIME(17,30,0))*(Orari!$X$6:$X$15>TIME(17,30,0)))+((Orari!$Y$6:$Y$15<=TIME(17,30,0))*(Orari!$Z$6:$Z$15>TIME(17,30,0))))) | K30: =SUMPRODUCT((ISNUMBER(SEARCH("🔑",Orari!$A$6:$A$15)))*(((Orari!$W$6:$W$15<=TIME(18,30,0))*(Orari!$X$6:$X$15>TIME(18,30,0)))+((Orari!$Y$6:$Y$15<=TIME(18,30,0))*(Orari!$Z$6:$Z$15>TIME(18,30,0))))) | L30: =SUMPRODUCT((ISNUMBER(SEARCH("🔑",Orari!$A$6:$A$15)))*(((Orari!$W$6:$W$15<=TIME(19,30,0))*(Orari!$X$6:$X$15>TIME(19,30,0)))+((Orari!$Y$6:$Y$15<=TIME(19,30,0))*(Orari!$Z$6:$Z$15>TIME(19,30,0))))) | M30: =SUMPRODUCT((ISNUMBER(SEARCH("🔑",Orari!$A$6:$A$15)))*(((Orari!$W$6:$W$15<=TIME(20,30,0))*(Orari!$X$6:$X$15>TIME(20,30,0)))+((Orari!$Y$6:$Y$15<=TIME(20,30,0))*(Orari!$Z$6:$Z$15>TIME(20,30,0)))))
